==========================================
SLURM_JOB_ID = 6214937
SLURM_JOB_NODELIST = d05-29
TMPDIR = /tmp/SLURM_6214937
==========================================
2021-10-17 21:48:41,983	WARNING experiment.py:302 -- No name detected on trainable. Using DEFAULT.
2021-10-17 21:48:41,983	INFO registry.py:66 -- Detected unknown callable for trainable. Converting to class.
2021-10-17 21:48:44,553	WARNING worker.py:1227 -- Warning: The actor ImplicitFunc is very large (62 MiB). Check that its definition is not implicitly capturing a large array or other object in scope. Tip: use ray.put() to put large objects in the Ray object store.
[2m[36m(pid=22053)[0m 2021-10-17 21:48:53,086	ERROR function_runner.py:266 -- Runner Thread raised error.
[2m[36m(pid=22053)[0m Traceback (most recent call last):
[2m[36m(pid=22053)[0m   File "/home1/pprabhu/.local/lib/python3.8/site-packages/ray/tune/function_runner.py", line 260, in run
[2m[36m(pid=22053)[0m     self._entrypoint()
[2m[36m(pid=22053)[0m   File "/home1/pprabhu/.local/lib/python3.8/site-packages/ray/tune/function_runner.py", line 328, in entrypoint
[2m[36m(pid=22053)[0m     return self._trainable_func(self.config, self._status_reporter,
[2m[36m(pid=22053)[0m   File "/home1/pprabhu/.local/lib/python3.8/site-packages/ray/util/tracing/tracing_helper.py", line 449, in _resume_span
[2m[36m(pid=22053)[0m     return method(self, *_args, **_kwargs)
[2m[36m(pid=22053)[0m   File "/home1/pprabhu/.local/lib/python3.8/site-packages/ray/tune/function_runner.py", line 594, in _trainable_func
[2m[36m(pid=22053)[0m     output = fn()
[2m[36m(pid=22053)[0m   File "/project/tbrun_769/qdec/source/neural_net.py", line 47, in train
[2m[36m(pid=22053)[0m     train_syndromes, train_error_labels, valid_syndromes, valid_error_labels = args
[2m[36m(pid=22053)[0m ValueError: too many values to unpack (expected 4)
[2m[36m(pid=22053)[0m Exception in thread Thread-2:
[2m[36m(pid=22053)[0m Traceback (most recent call last):
[2m[36m(pid=22053)[0m   File "/project/tbrun_769/envs/qdec/lib/python3.8/threading.py", line 932, in _bootstrap_inner
[2m[36m(pid=22053)[0m     self.run()
[2m[36m(pid=22053)[0m   File "/home1/pprabhu/.local/lib/python3.8/site-packages/ray/tune/function_runner.py", line 279, in run
[2m[36m(pid=22053)[0m     raise e
[2m[36m(pid=22053)[0m   File "/home1/pprabhu/.local/lib/python3.8/site-packages/ray/tune/function_runner.py", line 260, in run
[2m[36m(pid=22053)[0m     self._entrypoint()
[2m[36m(pid=22053)[0m   File "/home1/pprabhu/.local/lib/python3.8/site-packages/ray/tune/function_runner.py", line 328, in entrypoint
[2m[36m(pid=22053)[0m     return self._trainable_func(self.config, self._status_reporter,
[2m[36m(pid=22053)[0m   File "/home1/pprabhu/.local/lib/python3.8/site-packages/ray/util/tracing/tracing_helper.py", line 449, in _resume_span
[2m[36m(pid=22053)[0m     return method(self, *_args, **_kwargs)
[2m[36m(pid=22053)[0m   File "/home1/pprabhu/.local/lib/python3.8/site-packages/ray/tune/function_runner.py", line 594, in _trainable_func
[2m[36m(pid=22053)[0m     output = fn()
[2m[36m(pid=22053)[0m   File "/project/tbrun_769/qdec/source/neural_net.py", line 47, in train
[2m[36m(pid=22053)[0m     train_syndromes, train_error_labels, valid_syndromes, valid_error_labels = args
[2m[36m(pid=22053)[0m ValueError: too many values to unpack (expected 4)
[2m[36m(pid=22061)[0m 2021-10-17 21:48:53,061	ERROR function_runner.py:266 -- Runner Thread raised error.
[2m[36m(pid=22061)[0m Traceback (most recent call last):
[2m[36m(pid=22061)[0m   File "/home1/pprabhu/.local/lib/python3.8/site-packages/ray/tune/function_runner.py", line 260, in run
[2m[36m(pid=22061)[0m     self._entrypoint()
[2m[36m(pid=22061)[0m   File "/home1/pprabhu/.local/lib/python3.8/site-packages/ray/tune/function_runner.py", line 328, in entrypoint
[2m[36m(pid=22061)[0m     return self._trainable_func(self.config, self._status_reporter,
[2m[36m(pid=22061)[0m   File "/home1/pprabhu/.local/lib/python3.8/site-packages/ray/util/tracing/tracing_helper.py", line 449, in _resume_span
[2m[36m(pid=22061)[0m     return method(self, *_args, **_kwargs)
[2m[36m(pid=22061)[0m   File "/home1/pprabhu/.local/lib/python3.8/site-packages/ray/tune/function_runner.py", line 594, in _trainable_func
[2m[36m(pid=22061)[0m     output = fn()
[2m[36m(pid=22061)[0m   File "/project/tbrun_769/qdec/source/neural_net.py", line 47, in train
[2m[36m(pid=22061)[0m     train_syndromes, train_error_labels, valid_syndromes, valid_error_labels = args
[2m[36m(pid=22061)[0m ValueError: too many values to unpack (expected 4)
[2m[36m(pid=22061)[0m Exception in thread Thread-2:
[2m[36m(pid=22061)[0m Traceback (most recent call last):
[2m[36m(pid=22061)[0m   File "/project/tbrun_769/envs/qdec/lib/python3.8/threading.py", line 932, in _bootstrap_inner
[2m[36m(pid=22061)[0m     self.run()
[2m[36m(pid=22061)[0m   File "/home1/pprabhu/.local/lib/python3.8/site-packages/ray/tune/function_runner.py", line 279, in run
[2m[36m(pid=22061)[0m     raise e
[2m[36m(pid=22061)[0m   File "/home1/pprabhu/.local/lib/python3.8/site-packages/ray/tune/function_runner.py", line 260, in run
[2m[36m(pid=22061)[0m     self._entrypoint()
[2m[36m(pid=22061)[0m   File "/home1/pprabhu/.local/lib/python3.8/site-packages/ray/tune/function_runner.py", line 328, in entrypoint
[2m[36m(pid=22061)[0m     return self._trainable_func(self.config, self._status_reporter,
[2m[36m(pid=22061)[0m   File "/home1/pprabhu/.local/lib/python3.8/site-packages/ray/util/tracing/tracing_helper.py", line 449, in _resume_span
[2m[36m(pid=22061)[0m     return method(self, *_args, **_kwargs)
[2m[36m(pid=22061)[0m   File "/home1/pprabhu/.local/lib/python3.8/site-packages/ray/tune/function_runner.py", line 594, in _trainable_func
[2m[36m(pid=22061)[0m     output = fn()
[2m[36m(pid=22061)[0m   File "/project/tbrun_769/qdec/source/neural_net.py", line 47, in train
[2m[36m(pid=22061)[0m     train_syndromes, train_error_labels, valid_syndromes, valid_error_labels = args
[2m[36m(pid=22061)[0m ValueError: too many values to unpack (expected 4)
2021-10-17 21:48:53,266	ERROR trial_runner.py:846 -- Trial DEFAULT_ab22e_00000: Error processing event.
Traceback (most recent call last):
  File "/home1/pprabhu/.local/lib/python3.8/site-packages/ray/tune/trial_runner.py", line 812, in _process_trial
    results = self.trial_executor.fetch_result(trial)
  File "/home1/pprabhu/.local/lib/python3.8/site-packages/ray/tune/ray_trial_executor.py", line 767, in fetch_result
    result = ray.get(trial_future[0], timeout=DEFAULT_GET_TIMEOUT)
  File "/home1/pprabhu/.local/lib/python3.8/site-packages/ray/_private/client_mode_hook.py", line 89, in wrapper
    return func(*args, **kwargs)
  File "/home1/pprabhu/.local/lib/python3.8/site-packages/ray/worker.py", line 1621, in get
    raise value.as_instanceof_cause()
ray.exceptions.RayTaskError(TuneError): [36mray::ImplicitFunc.train_buffered()[39m (pid=22061, ip=10.125.19.203, repr=<types.ImplicitFunc object at 0x7fb454016160>)
  File "/home1/pprabhu/.local/lib/python3.8/site-packages/ray/tune/trainable.py", line 189, in train_buffered
    result = self.train()
  File "/home1/pprabhu/.local/lib/python3.8/site-packages/ray/tune/trainable.py", line 248, in train
    result = self.step()
  File "/home1/pprabhu/.local/lib/python3.8/site-packages/ray/tune/function_runner.py", line 379, in step
    self._report_thread_runner_error(block=True)
  File "/home1/pprabhu/.local/lib/python3.8/site-packages/ray/tune/function_runner.py", line 526, in _report_thread_runner_error
    raise TuneError(
ray.tune.error.TuneError: Trial raised an exception. Traceback:
[36mray::ImplicitFunc.train_buffered()[39m (pid=22061, ip=10.125.19.203, repr=<types.ImplicitFunc object at 0x7fb454016160>)
  File "/home1/pprabhu/.local/lib/python3.8/site-packages/ray/tune/function_runner.py", line 260, in run
    self._entrypoint()
  File "/home1/pprabhu/.local/lib/python3.8/site-packages/ray/tune/function_runner.py", line 328, in entrypoint
    return self._trainable_func(self.config, self._status_reporter,
  File "/home1/pprabhu/.local/lib/python3.8/site-packages/ray/tune/function_runner.py", line 594, in _trainable_func
    output = fn()
  File "/project/tbrun_769/qdec/source/neural_net.py", line 47, in train
    train_syndromes, train_error_labels, valid_syndromes, valid_error_labels = args
ValueError: too many values to unpack (expected 4)
2021-10-17 21:48:53,290	ERROR trial_runner.py:846 -- Trial DEFAULT_ab22e_00001: Error processing event.
Traceback (most recent call last):
  File "/home1/pprabhu/.local/lib/python3.8/site-packages/ray/tune/trial_runner.py", line 812, in _process_trial
    results = self.trial_executor.fetch_result(trial)
  File "/home1/pprabhu/.local/lib/python3.8/site-packages/ray/tune/ray_trial_executor.py", line 767, in fetch_result
    result = ray.get(trial_future[0], timeout=DEFAULT_GET_TIMEOUT)
  File "/home1/pprabhu/.local/lib/python3.8/site-packages/ray/_private/client_mode_hook.py", line 89, in wrapper
    return func(*args, **kwargs)
  File "/home1/pprabhu/.local/lib/python3.8/site-packages/ray/worker.py", line 1621, in get
    raise value.as_instanceof_cause()
ray.exceptions.RayTaskError(TuneError): [36mray::ImplicitFunc.train_buffered()[39m (pid=22053, ip=10.125.19.203, repr=<types.ImplicitFunc object at 0x7fe28dc10e50>)
  File "/home1/pprabhu/.local/lib/python3.8/site-packages/ray/tune/trainable.py", line 189, in train_buffered
    result = self.train()
  File "/home1/pprabhu/.local/lib/python3.8/site-packages/ray/tune/trainable.py", line 248, in train
    result = self.step()
  File "/home1/pprabhu/.local/lib/python3.8/site-packages/ray/tune/function_runner.py", line 379, in step
    self._report_thread_runner_error(block=True)
  File "/home1/pprabhu/.local/lib/python3.8/site-packages/ray/tune/function_runner.py", line 526, in _report_thread_runner_error
    raise TuneError(
ray.tune.error.TuneError: Trial raised an exception. Traceback:
[36mray::ImplicitFunc.train_buffered()[39m (pid=22053, ip=10.125.19.203, repr=<types.ImplicitFunc object at 0x7fe28dc10e50>)
  File "/home1/pprabhu/.local/lib/python3.8/site-packages/ray/tune/function_runner.py", line 260, in run
    self._entrypoint()
  File "/home1/pprabhu/.local/lib/python3.8/site-packages/ray/tune/function_runner.py", line 328, in entrypoint
    return self._trainable_func(self.config, self._status_reporter,
  File "/home1/pprabhu/.local/lib/python3.8/site-packages/ray/tune/function_runner.py", line 594, in _trainable_func
    output = fn()
  File "/project/tbrun_769/qdec/source/neural_net.py", line 47, in train
    train_syndromes, train_error_labels, valid_syndromes, valid_error_labels = args
ValueError: too many values to unpack (expected 4)
[2m[36m(pid=22062)[0m 2021-10-17 21:48:54,101	ERROR function_runner.py:266 -- Runner Thread raised error.
[2m[36m(pid=22062)[0m Traceback (most recent call last):
[2m[36m(pid=22062)[0m   File "/home1/pprabhu/.local/lib/python3.8/site-packages/ray/tune/function_runner.py", line 260, in run
[2m[36m(pid=22062)[0m     self._entrypoint()
[2m[36m(pid=22062)[0m   File "/home1/pprabhu/.local/lib/python3.8/site-packages/ray/tune/function_runner.py", line 328, in entrypoint
[2m[36m(pid=22062)[0m     return self._trainable_func(self.config, self._status_reporter,
[2m[36m(pid=22062)[0m   File "/home1/pprabhu/.local/lib/python3.8/site-packages/ray/util/tracing/tracing_helper.py", line 449, in _resume_span
[2m[36m(pid=22062)[0m     return method(self, *_args, **_kwargs)
[2m[36m(pid=22062)[0m   File "/home1/pprabhu/.local/lib/python3.8/site-packages/ray/tune/function_runner.py", line 594, in _trainable_func
[2m[36m(pid=22062)[0m     output = fn()
[2m[36m(pid=22062)[0m   File "/project/tbrun_769/qdec/source/neural_net.py", line 47, in train
[2m[36m(pid=22062)[0m     train_syndromes, train_error_labels, valid_syndromes, valid_error_labels = args
[2m[36m(pid=22062)[0m ValueError: too many values to unpack (expected 4)
[2m[36m(pid=22062)[0m Exception in thread Thread-2:
[2m[36m(pid=22062)[0m Traceback (most recent call last):
[2m[36m(pid=22062)[0m   File "/project/tbrun_769/envs/qdec/lib/python3.8/threading.py", line 932, in _bootstrap_inner
[2m[36m(pid=22062)[0m     self.run()
[2m[36m(pid=22062)[0m   File "/home1/pprabhu/.local/lib/python3.8/site-packages/ray/tune/function_runner.py", line 279, in run
[2m[36m(pid=22062)[0m     raise e
[2m[36m(pid=22062)[0m   File "/home1/pprabhu/.local/lib/python3.8/site-packages/ray/tune/function_runner.py", line 260, in run
[2m[36m(pid=22062)[0m     self._entrypoint()
[2m[36m(pid=22062)[0m   File "/home1/pprabhu/.local/lib/python3.8/site-packages/ray/tune/function_runner.py", line 328, in entrypoint
[2m[36m(pid=22062)[0m     return self._trainable_func(self.config, self._status_reporter,
[2m[36m(pid=22062)[0m   File "/home1/pprabhu/.local/lib/python3.8/site-packages/ray/util/tracing/tracing_helper.py", line 449, in _resume_span
[2m[36m(pid=22062)[0m     return method(self, *_args, **_kwargs)
[2m[36m(pid=22062)[0m   File "/home1/pprabhu/.local/lib/python3.8/site-packages/ray/tune/function_runner.py", line 594, in _trainable_func
[2m[36m(pid=22062)[0m     output = fn()
[2m[36m(pid=22062)[0m   File "/project/tbrun_769/qdec/source/neural_net.py", line 47, in train
[2m[36m(pid=22062)[0m     train_syndromes, train_error_labels, valid_syndromes, valid_error_labels = args
[2m[36m(pid=22062)[0m ValueError: too many values to unpack (expected 4)
[2m[36m(pid=22057)[0m 2021-10-17 21:48:54,222	ERROR function_runner.py:266 -- Runner Thread raised error.
[2m[36m(pid=22057)[0m Traceback (most recent call last):
[2m[36m(pid=22057)[0m   File "/home1/pprabhu/.local/lib/python3.8/site-packages/ray/tune/function_runner.py", line 260, in run
[2m[36m(pid=22057)[0m     self._entrypoint()
[2m[36m(pid=22057)[0m   File "/home1/pprabhu/.local/lib/python3.8/site-packages/ray/tune/function_runner.py", line 328, in entrypoint
[2m[36m(pid=22057)[0m     return self._trainable_func(self.config, self._status_reporter,
[2m[36m(pid=22057)[0m   File "/home1/pprabhu/.local/lib/python3.8/site-packages/ray/util/tracing/tracing_helper.py", line 449, in _resume_span
[2m[36m(pid=22057)[0m     return method(self, *_args, **_kwargs)
[2m[36m(pid=22057)[0m   File "/home1/pprabhu/.local/lib/python3.8/site-packages/ray/tune/function_runner.py", line 594, in _trainable_func
[2m[36m(pid=22057)[0m     output = fn()
[2m[36m(pid=22057)[0m   File "/project/tbrun_769/qdec/source/neural_net.py", line 47, in train
[2m[36m(pid=22057)[0m     train_syndromes, train_error_labels, valid_syndromes, valid_error_labels = args
[2m[36m(pid=22057)[0m ValueError: too many values to unpack (expected 4)
[2m[36m(pid=22057)[0m Exception in thread Thread-2:
[2m[36m(pid=22057)[0m Traceback (most recent call last):
[2m[36m(pid=22057)[0m   File "/project/tbrun_769/envs/qdec/lib/python3.8/threading.py", line 932, in _bootstrap_inner
[2m[36m(pid=22057)[0m     self.run()
[2m[36m(pid=22057)[0m   File "/home1/pprabhu/.local/lib/python3.8/site-packages/ray/tune/function_runner.py", line 279, in run
[2m[36m(pid=22057)[0m     raise e
[2m[36m(pid=22057)[0m   File "/home1/pprabhu/.local/lib/python3.8/site-packages/ray/tune/function_runner.py", line 260, in run
[2m[36m(pid=22057)[0m     self._entrypoint()
[2m[36m(pid=22057)[0m   File "/home1/pprabhu/.local/lib/python3.8/site-packages/ray/tune/function_runner.py", line 328, in entrypoint
[2m[36m(pid=22057)[0m     return self._trainable_func(self.config, self._status_reporter,
[2m[36m(pid=22057)[0m   File "/home1/pprabhu/.local/lib/python3.8/site-packages/ray/util/tracing/tracing_helper.py", line 449, in _resume_span
[2m[36m(pid=22057)[0m     return method(self, *_args, **_kwargs)
[2m[36m(pid=22057)[0m   File "/home1/pprabhu/.local/lib/python3.8/site-packages/ray/tune/function_runner.py", line 594, in _trainable_func
[2m[36m(pid=22057)[0m     output = fn()
[2m[36m(pid=22057)[0m   File "/project/tbrun_769/qdec/source/neural_net.py", line 47, in train
[2m[36m(pid=22057)[0m     train_syndromes, train_error_labels, valid_syndromes, valid_error_labels = args
[2m[36m(pid=22057)[0m ValueError: too many values to unpack (expected 4)
2021-10-17 21:48:54,304	ERROR trial_runner.py:846 -- Trial DEFAULT_ab22e_00002: Error processing event.
Traceback (most recent call last):
  File "/home1/pprabhu/.local/lib/python3.8/site-packages/ray/tune/trial_runner.py", line 812, in _process_trial
    results = self.trial_executor.fetch_result(trial)
  File "/home1/pprabhu/.local/lib/python3.8/site-packages/ray/tune/ray_trial_executor.py", line 767, in fetch_result
    result = ray.get(trial_future[0], timeout=DEFAULT_GET_TIMEOUT)
  File "/home1/pprabhu/.local/lib/python3.8/site-packages/ray/_private/client_mode_hook.py", line 89, in wrapper
    return func(*args, **kwargs)
  File "/home1/pprabhu/.local/lib/python3.8/site-packages/ray/worker.py", line 1621, in get
    raise value.as_instanceof_cause()
ray.exceptions.RayTaskError(TuneError): [36mray::ImplicitFunc.train_buffered()[39m (pid=22062, ip=10.125.19.203, repr=<types.ImplicitFunc object at 0x7f90df350fa0>)
  File "/home1/pprabhu/.local/lib/python3.8/site-packages/ray/tune/trainable.py", line 189, in train_buffered
    result = self.train()
  File "/home1/pprabhu/.local/lib/python3.8/site-packages/ray/tune/trainable.py", line 248, in train
    result = self.step()
  File "/home1/pprabhu/.local/lib/python3.8/site-packages/ray/tune/function_runner.py", line 379, in step
    self._report_thread_runner_error(block=True)
  File "/home1/pprabhu/.local/lib/python3.8/site-packages/ray/tune/function_runner.py", line 526, in _report_thread_runner_error
    raise TuneError(
ray.tune.error.TuneError: Trial raised an exception. Traceback:
[36mray::ImplicitFunc.train_buffered()[39m (pid=22062, ip=10.125.19.203, repr=<types.ImplicitFunc object at 0x7f90df350fa0>)
  File "/home1/pprabhu/.local/lib/python3.8/site-packages/ray/tune/function_runner.py", line 260, in run
    self._entrypoint()
  File "/home1/pprabhu/.local/lib/python3.8/site-packages/ray/tune/function_runner.py", line 328, in entrypoint
    return self._trainable_func(self.config, self._status_reporter,
  File "/home1/pprabhu/.local/lib/python3.8/site-packages/ray/tune/function_runner.py", line 594, in _trainable_func
    output = fn()
  File "/project/tbrun_769/qdec/source/neural_net.py", line 47, in train
    train_syndromes, train_error_labels, valid_syndromes, valid_error_labels = args
ValueError: too many values to unpack (expected 4)
2021-10-17 21:48:54,425	ERROR trial_runner.py:846 -- Trial DEFAULT_ab22e_00003: Error processing event.
Traceback (most recent call last):
  File "/home1/pprabhu/.local/lib/python3.8/site-packages/ray/tune/trial_runner.py", line 812, in _process_trial
    results = self.trial_executor.fetch_result(trial)
  File "/home1/pprabhu/.local/lib/python3.8/site-packages/ray/tune/ray_trial_executor.py", line 767, in fetch_result
    result = ray.get(trial_future[0], timeout=DEFAULT_GET_TIMEOUT)
  File "/home1/pprabhu/.local/lib/python3.8/site-packages/ray/_private/client_mode_hook.py", line 89, in wrapper
    return func(*args, **kwargs)
  File "/home1/pprabhu/.local/lib/python3.8/site-packages/ray/worker.py", line 1621, in get
    raise value.as_instanceof_cause()
ray.exceptions.RayTaskError(TuneError): [36mray::ImplicitFunc.train_buffered()[39m (pid=22057, ip=10.125.19.203, repr=<types.ImplicitFunc object at 0x7f874b349fa0>)
  File "/home1/pprabhu/.local/lib/python3.8/site-packages/ray/tune/trainable.py", line 189, in train_buffered
    result = self.train()
  File "/home1/pprabhu/.local/lib/python3.8/site-packages/ray/tune/trainable.py", line 248, in train
    result = self.step()
  File "/home1/pprabhu/.local/lib/python3.8/site-packages/ray/tune/function_runner.py", line 379, in step
    self._report_thread_runner_error(block=True)
  File "/home1/pprabhu/.local/lib/python3.8/site-packages/ray/tune/function_runner.py", line 526, in _report_thread_runner_error
    raise TuneError(
ray.tune.error.TuneError: Trial raised an exception. Traceback:
[36mray::ImplicitFunc.train_buffered()[39m (pid=22057, ip=10.125.19.203, repr=<types.ImplicitFunc object at 0x7f874b349fa0>)
  File "/home1/pprabhu/.local/lib/python3.8/site-packages/ray/tune/function_runner.py", line 260, in run
    self._entrypoint()
  File "/home1/pprabhu/.local/lib/python3.8/site-packages/ray/tune/function_runner.py", line 328, in entrypoint
    return self._trainable_func(self.config, self._status_reporter,
  File "/home1/pprabhu/.local/lib/python3.8/site-packages/ray/tune/function_runner.py", line 594, in _trainable_func
    output = fn()
  File "/project/tbrun_769/qdec/source/neural_net.py", line 47, in train
    train_syndromes, train_error_labels, valid_syndromes, valid_error_labels = args
ValueError: too many values to unpack (expected 4)
[2m[36m(pid=22052)[0m 2021-10-17 21:48:55,220	ERROR function_runner.py:266 -- Runner Thread raised error.
[2m[36m(pid=22052)[0m Traceback (most recent call last):
[2m[36m(pid=22052)[0m   File "/home1/pprabhu/.local/lib/python3.8/site-packages/ray/tune/function_runner.py", line 260, in run
[2m[36m(pid=22052)[0m     self._entrypoint()
[2m[36m(pid=22052)[0m   File "/home1/pprabhu/.local/lib/python3.8/site-packages/ray/tune/function_runner.py", line 328, in entrypoint
[2m[36m(pid=22052)[0m     return self._trainable_func(self.config, self._status_reporter,
[2m[36m(pid=22052)[0m   File "/home1/pprabhu/.local/lib/python3.8/site-packages/ray/util/tracing/tracing_helper.py", line 449, in _resume_span
[2m[36m(pid=22052)[0m     return method(self, *_args, **_kwargs)
[2m[36m(pid=22052)[0m   File "/home1/pprabhu/.local/lib/python3.8/site-packages/ray/tune/function_runner.py", line 594, in _trainable_func
[2m[36m(pid=22052)[0m     output = fn()
[2m[36m(pid=22052)[0m   File "/project/tbrun_769/qdec/source/neural_net.py", line 47, in train
[2m[36m(pid=22052)[0m     train_syndromes, train_error_labels, valid_syndromes, valid_error_labels = args
[2m[36m(pid=22052)[0m ValueError: too many values to unpack (expected 4)
[2m[36m(pid=22052)[0m Exception in thread Thread-2:
[2m[36m(pid=22052)[0m Traceback (most recent call last):
[2m[36m(pid=22052)[0m   File "/project/tbrun_769/envs/qdec/lib/python3.8/threading.py", line 932, in _bootstrap_inner
[2m[36m(pid=22052)[0m     self.run()
[2m[36m(pid=22052)[0m   File "/home1/pprabhu/.local/lib/python3.8/site-packages/ray/tune/function_runner.py", line 279, in run
[2m[36m(pid=22052)[0m     raise e
[2m[36m(pid=22052)[0m   File "/home1/pprabhu/.local/lib/python3.8/site-packages/ray/tune/function_runner.py", line 260, in run
[2m[36m(pid=22052)[0m     self._entrypoint()
[2m[36m(pid=22052)[0m   File "/home1/pprabhu/.local/lib/python3.8/site-packages/ray/tune/function_runner.py", line 328, in entrypoint
[2m[36m(pid=22052)[0m     return self._trainable_func(self.config, self._status_reporter,
[2m[36m(pid=22052)[0m   File "/home1/pprabhu/.local/lib/python3.8/site-packages/ray/util/tracing/tracing_helper.py", line 449, in _resume_span
[2m[36m(pid=22052)[0m     return method(self, *_args, **_kwargs)
[2m[36m(pid=22052)[0m   File "/home1/pprabhu/.local/lib/python3.8/site-packages/ray/tune/function_runner.py", line 594, in _trainable_func
[2m[36m(pid=22052)[0m     output = fn()
[2m[36m(pid=22052)[0m   File "/project/tbrun_769/qdec/source/neural_net.py", line 47, in train
[2m[36m(pid=22052)[0m     train_syndromes, train_error_labels, valid_syndromes, valid_error_labels = args
[2m[36m(pid=22052)[0m ValueError: too many values to unpack (expected 4)
[2m[36m(pid=22063)[0m 2021-10-17 21:48:55,210	ERROR function_runner.py:266 -- Runner Thread raised error.
[2m[36m(pid=22063)[0m Traceback (most recent call last):
[2m[36m(pid=22063)[0m   File "/home1/pprabhu/.local/lib/python3.8/site-packages/ray/tune/function_runner.py", line 260, in run
[2m[36m(pid=22063)[0m     self._entrypoint()
[2m[36m(pid=22063)[0m   File "/home1/pprabhu/.local/lib/python3.8/site-packages/ray/tune/function_runner.py", line 328, in entrypoint
[2m[36m(pid=22063)[0m     return self._trainable_func(self.config, self._status_reporter,
[2m[36m(pid=22063)[0m   File "/home1/pprabhu/.local/lib/python3.8/site-packages/ray/util/tracing/tracing_helper.py", line 449, in _resume_span
[2m[36m(pid=22063)[0m     return method(self, *_args, **_kwargs)
[2m[36m(pid=22063)[0m   File "/home1/pprabhu/.local/lib/python3.8/site-packages/ray/tune/function_runner.py", line 594, in _trainable_func
[2m[36m(pid=22063)[0m     output = fn()
[2m[36m(pid=22063)[0m   File "/project/tbrun_769/qdec/source/neural_net.py", line 47, in train
[2m[36m(pid=22063)[0m     train_syndromes, train_error_labels, valid_syndromes, valid_error_labels = args
[2m[36m(pid=22063)[0m ValueError: too many values to unpack (expected 4)
[2m[36m(pid=22063)[0m Exception in thread Thread-2:
[2m[36m(pid=22063)[0m Traceback (most recent call last):
[2m[36m(pid=22063)[0m   File "/project/tbrun_769/envs/qdec/lib/python3.8/threading.py", line 932, in _bootstrap_inner
[2m[36m(pid=22063)[0m     self.run()
[2m[36m(pid=22063)[0m   File "/home1/pprabhu/.local/lib/python3.8/site-packages/ray/tune/function_runner.py", line 279, in run
[2m[36m(pid=22063)[0m     raise e
[2m[36m(pid=22063)[0m   File "/home1/pprabhu/.local/lib/python3.8/site-packages/ray/tune/function_runner.py", line 260, in run
[2m[36m(pid=22063)[0m     self._entrypoint()
[2m[36m(pid=22063)[0m   File "/home1/pprabhu/.local/lib/python3.8/site-packages/ray/tune/function_runner.py", line 328, in entrypoint
[2m[36m(pid=22063)[0m     return self._trainable_func(self.config, self._status_reporter,
[2m[36m(pid=22063)[0m   File "/home1/pprabhu/.local/lib/python3.8/site-packages/ray/util/tracing/tracing_helper.py", line 449, in _resume_span
[2m[36m(pid=22063)[0m     return method(self, *_args, **_kwargs)
[2m[36m(pid=22063)[0m   File "/home1/pprabhu/.local/lib/python3.8/site-packages/ray/tune/function_runner.py", line 594, in _trainable_func
[2m[36m(pid=22063)[0m     output = fn()
[2m[36m(pid=22063)[0m   File "/project/tbrun_769/qdec/source/neural_net.py", line 47, in train
[2m[36m(pid=22063)[0m     train_syndromes, train_error_labels, valid_syndromes, valid_error_labels = args
[2m[36m(pid=22063)[0m ValueError: too many values to unpack (expected 4)
2021-10-17 21:48:55,413	ERROR trial_runner.py:846 -- Trial DEFAULT_ab22e_00005: Error processing event.
Traceback (most recent call last):
  File "/home1/pprabhu/.local/lib/python3.8/site-packages/ray/tune/trial_runner.py", line 812, in _process_trial
    results = self.trial_executor.fetch_result(trial)
  File "/home1/pprabhu/.local/lib/python3.8/site-packages/ray/tune/ray_trial_executor.py", line 767, in fetch_result
    result = ray.get(trial_future[0], timeout=DEFAULT_GET_TIMEOUT)
  File "/home1/pprabhu/.local/lib/python3.8/site-packages/ray/_private/client_mode_hook.py", line 89, in wrapper
    return func(*args, **kwargs)
  File "/home1/pprabhu/.local/lib/python3.8/site-packages/ray/worker.py", line 1621, in get
    raise value.as_instanceof_cause()
ray.exceptions.RayTaskError(TuneError): [36mray::ImplicitFunc.train_buffered()[39m (pid=22063, ip=10.125.19.203, repr=<types.ImplicitFunc object at 0x7f60102b4fa0>)
  File "/home1/pprabhu/.local/lib/python3.8/site-packages/ray/tune/trainable.py", line 189, in train_buffered
    result = self.train()
  File "/home1/pprabhu/.local/lib/python3.8/site-packages/ray/tune/trainable.py", line 248, in train
    result = self.step()
  File "/home1/pprabhu/.local/lib/python3.8/site-packages/ray/tune/function_runner.py", line 379, in step
    self._report_thread_runner_error(block=True)
  File "/home1/pprabhu/.local/lib/python3.8/site-packages/ray/tune/function_runner.py", line 526, in _report_thread_runner_error
    raise TuneError(
ray.tune.error.TuneError: Trial raised an exception. Traceback:
[36mray::ImplicitFunc.train_buffered()[39m (pid=22063, ip=10.125.19.203, repr=<types.ImplicitFunc object at 0x7f60102b4fa0>)
  File "/home1/pprabhu/.local/lib/python3.8/site-packages/ray/tune/function_runner.py", line 260, in run
    self._entrypoint()
  File "/home1/pprabhu/.local/lib/python3.8/site-packages/ray/tune/function_runner.py", line 328, in entrypoint
    return self._trainable_func(self.config, self._status_reporter,
  File "/home1/pprabhu/.local/lib/python3.8/site-packages/ray/tune/function_runner.py", line 594, in _trainable_func
    output = fn()
  File "/project/tbrun_769/qdec/source/neural_net.py", line 47, in train
    train_syndromes, train_error_labels, valid_syndromes, valid_error_labels = args
ValueError: too many values to unpack (expected 4)
2021-10-17 21:48:55,435	ERROR trial_runner.py:846 -- Trial DEFAULT_ab22e_00004: Error processing event.
Traceback (most recent call last):
  File "/home1/pprabhu/.local/lib/python3.8/site-packages/ray/tune/trial_runner.py", line 812, in _process_trial
    results = self.trial_executor.fetch_result(trial)
  File "/home1/pprabhu/.local/lib/python3.8/site-packages/ray/tune/ray_trial_executor.py", line 767, in fetch_result
    result = ray.get(trial_future[0], timeout=DEFAULT_GET_TIMEOUT)
  File "/home1/pprabhu/.local/lib/python3.8/site-packages/ray/_private/client_mode_hook.py", line 89, in wrapper
    return func(*args, **kwargs)
  File "/home1/pprabhu/.local/lib/python3.8/site-packages/ray/worker.py", line 1621, in get
    raise value.as_instanceof_cause()
ray.exceptions.RayTaskError(TuneError): [36mray::ImplicitFunc.train_buffered()[39m (pid=22052, ip=10.125.19.203, repr=<types.ImplicitFunc object at 0x7f4f4c0ebfa0>)
  File "/home1/pprabhu/.local/lib/python3.8/site-packages/ray/tune/trainable.py", line 189, in train_buffered
    result = self.train()
  File "/home1/pprabhu/.local/lib/python3.8/site-packages/ray/tune/trainable.py", line 248, in train
    result = self.step()
  File "/home1/pprabhu/.local/lib/python3.8/site-packages/ray/tune/function_runner.py", line 379, in step
    self._report_thread_runner_error(block=True)
  File "/home1/pprabhu/.local/lib/python3.8/site-packages/ray/tune/function_runner.py", line 526, in _report_thread_runner_error
    raise TuneError(
ray.tune.error.TuneError: Trial raised an exception. Traceback:
[36mray::ImplicitFunc.train_buffered()[39m (pid=22052, ip=10.125.19.203, repr=<types.ImplicitFunc object at 0x7f4f4c0ebfa0>)
  File "/home1/pprabhu/.local/lib/python3.8/site-packages/ray/tune/function_runner.py", line 260, in run
    self._entrypoint()
  File "/home1/pprabhu/.local/lib/python3.8/site-packages/ray/tune/function_runner.py", line 328, in entrypoint
    return self._trainable_func(self.config, self._status_reporter,
  File "/home1/pprabhu/.local/lib/python3.8/site-packages/ray/tune/function_runner.py", line 594, in _trainable_func
    output = fn()
  File "/project/tbrun_769/qdec/source/neural_net.py", line 47, in train
    train_syndromes, train_error_labels, valid_syndromes, valid_error_labels = args
ValueError: too many values to unpack (expected 4)
[2m[36m(pid=22059)[0m 2021-10-17 21:48:56,157	ERROR function_runner.py:266 -- Runner Thread raised error.
[2m[36m(pid=22059)[0m Traceback (most recent call last):
[2m[36m(pid=22059)[0m   File "/home1/pprabhu/.local/lib/python3.8/site-packages/ray/tune/function_runner.py", line 260, in run
[2m[36m(pid=22059)[0m     self._entrypoint()
[2m[36m(pid=22059)[0m   File "/home1/pprabhu/.local/lib/python3.8/site-packages/ray/tune/function_runner.py", line 328, in entrypoint
[2m[36m(pid=22059)[0m     return self._trainable_func(self.config, self._status_reporter,
[2m[36m(pid=22059)[0m   File "/home1/pprabhu/.local/lib/python3.8/site-packages/ray/util/tracing/tracing_helper.py", line 449, in _resume_span
[2m[36m(pid=22059)[0m     return method(self, *_args, **_kwargs)
[2m[36m(pid=22059)[0m   File "/home1/pprabhu/.local/lib/python3.8/site-packages/ray/tune/function_runner.py", line 594, in _trainable_func
[2m[36m(pid=22059)[0m     output = fn()
[2m[36m(pid=22059)[0m   File "/project/tbrun_769/qdec/source/neural_net.py", line 47, in train
[2m[36m(pid=22059)[0m     train_syndromes, train_error_labels, valid_syndromes, valid_error_labels = args
[2m[36m(pid=22059)[0m ValueError: too many values to unpack (expected 4)
[2m[36m(pid=22059)[0m Exception in thread Thread-2:
[2m[36m(pid=22059)[0m Traceback (most recent call last):
[2m[36m(pid=22059)[0m   File "/project/tbrun_769/envs/qdec/lib/python3.8/threading.py", line 932, in _bootstrap_inner
[2m[36m(pid=22059)[0m     self.run()
[2m[36m(pid=22059)[0m   File "/home1/pprabhu/.local/lib/python3.8/site-packages/ray/tune/function_runner.py", line 279, in run
[2m[36m(pid=22059)[0m     raise e
[2m[36m(pid=22059)[0m   File "/home1/pprabhu/.local/lib/python3.8/site-packages/ray/tune/function_runner.py", line 260, in run
[2m[36m(pid=22059)[0m     self._entrypoint()
[2m[36m(pid=22059)[0m   File "/home1/pprabhu/.local/lib/python3.8/site-packages/ray/tune/function_runner.py", line 328, in entrypoint
[2m[36m(pid=22059)[0m     return self._trainable_func(self.config, self._status_reporter,
[2m[36m(pid=22059)[0m   File "/home1/pprabhu/.local/lib/python3.8/site-packages/ray/util/tracing/tracing_helper.py", line 449, in _resume_span
[2m[36m(pid=22059)[0m     return method(self, *_args, **_kwargs)
[2m[36m(pid=22059)[0m   File "/home1/pprabhu/.local/lib/python3.8/site-packages/ray/tune/function_runner.py", line 594, in _trainable_func
[2m[36m(pid=22059)[0m     output = fn()
[2m[36m(pid=22059)[0m   File "/project/tbrun_769/qdec/source/neural_net.py", line 47, in train
[2m[36m(pid=22059)[0m     train_syndromes, train_error_labels, valid_syndromes, valid_error_labels = args
[2m[36m(pid=22059)[0m ValueError: too many values to unpack (expected 4)
[2m[36m(pid=22064)[0m 2021-10-17 21:48:56,181	ERROR function_runner.py:266 -- Runner Thread raised error.
[2m[36m(pid=22064)[0m Traceback (most recent call last):
[2m[36m(pid=22064)[0m   File "/home1/pprabhu/.local/lib/python3.8/site-packages/ray/tune/function_runner.py", line 260, in run
[2m[36m(pid=22064)[0m     self._entrypoint()
[2m[36m(pid=22064)[0m   File "/home1/pprabhu/.local/lib/python3.8/site-packages/ray/tune/function_runner.py", line 328, in entrypoint
[2m[36m(pid=22064)[0m     return self._trainable_func(self.config, self._status_reporter,
[2m[36m(pid=22064)[0m   File "/home1/pprabhu/.local/lib/python3.8/site-packages/ray/util/tracing/tracing_helper.py", line 449, in _resume_span
[2m[36m(pid=22064)[0m     return method(self, *_args, **_kwargs)
[2m[36m(pid=22064)[0m   File "/home1/pprabhu/.local/lib/python3.8/site-packages/ray/tune/function_runner.py", line 594, in _trainable_func
[2m[36m(pid=22064)[0m     output = fn()
[2m[36m(pid=22064)[0m   File "/project/tbrun_769/qdec/source/neural_net.py", line 47, in train
[2m[36m(pid=22064)[0m     train_syndromes, train_error_labels, valid_syndromes, valid_error_labels = args
[2m[36m(pid=22064)[0m ValueError: too many values to unpack (expected 4)
[2m[36m(pid=22064)[0m Exception in thread Thread-2:
[2m[36m(pid=22064)[0m Traceback (most recent call last):
[2m[36m(pid=22064)[0m   File "/project/tbrun_769/envs/qdec/lib/python3.8/threading.py", line 932, in _bootstrap_inner
[2m[36m(pid=22064)[0m     self.run()
[2m[36m(pid=22064)[0m   File "/home1/pprabhu/.local/lib/python3.8/site-packages/ray/tune/function_runner.py", line 279, in run
[2m[36m(pid=22064)[0m     raise e
[2m[36m(pid=22064)[0m   File "/home1/pprabhu/.local/lib/python3.8/site-packages/ray/tune/function_runner.py", line 260, in run
[2m[36m(pid=22064)[0m     self._entrypoint()
[2m[36m(pid=22064)[0m   File "/home1/pprabhu/.local/lib/python3.8/site-packages/ray/tune/function_runner.py", line 328, in entrypoint
[2m[36m(pid=22064)[0m     return self._trainable_func(self.config, self._status_reporter,
[2m[36m(pid=22064)[0m   File "/home1/pprabhu/.local/lib/python3.8/site-packages/ray/util/tracing/tracing_helper.py", line 449, in _resume_span
[2m[36m(pid=22064)[0m     return method(self, *_args, **_kwargs)
[2m[36m(pid=22064)[0m   File "/home1/pprabhu/.local/lib/python3.8/site-packages/ray/tune/function_runner.py", line 594, in _trainable_func
[2m[36m(pid=22064)[0m     output = fn()
[2m[36m(pid=22064)[0m   File "/project/tbrun_769/qdec/source/neural_net.py", line 47, in train
[2m[36m(pid=22064)[0m     train_syndromes, train_error_labels, valid_syndromes, valid_error_labels = args
[2m[36m(pid=22064)[0m ValueError: too many values to unpack (expected 4)
2021-10-17 21:48:56,360	ERROR trial_runner.py:846 -- Trial DEFAULT_ab22e_00006: Error processing event.
Traceback (most recent call last):
  File "/home1/pprabhu/.local/lib/python3.8/site-packages/ray/tune/trial_runner.py", line 812, in _process_trial
    results = self.trial_executor.fetch_result(trial)
  File "/home1/pprabhu/.local/lib/python3.8/site-packages/ray/tune/ray_trial_executor.py", line 767, in fetch_result
    result = ray.get(trial_future[0], timeout=DEFAULT_GET_TIMEOUT)
  File "/home1/pprabhu/.local/lib/python3.8/site-packages/ray/_private/client_mode_hook.py", line 89, in wrapper
    return func(*args, **kwargs)
  File "/home1/pprabhu/.local/lib/python3.8/site-packages/ray/worker.py", line 1621, in get
    raise value.as_instanceof_cause()
ray.exceptions.RayTaskError(TuneError): [36mray::ImplicitFunc.train_buffered()[39m (pid=22059, ip=10.125.19.203, repr=<types.ImplicitFunc object at 0x7f784287dfa0>)
  File "/home1/pprabhu/.local/lib/python3.8/site-packages/ray/tune/trainable.py", line 189, in train_buffered
    result = self.train()
  File "/home1/pprabhu/.local/lib/python3.8/site-packages/ray/tune/trainable.py", line 248, in train
    result = self.step()
  File "/home1/pprabhu/.local/lib/python3.8/site-packages/ray/tune/function_runner.py", line 379, in step
    self._report_thread_runner_error(block=True)
  File "/home1/pprabhu/.local/lib/python3.8/site-packages/ray/tune/function_runner.py", line 526, in _report_thread_runner_error
    raise TuneError(
ray.tune.error.TuneError: Trial raised an exception. Traceback:
[36mray::ImplicitFunc.train_buffered()[39m (pid=22059, ip=10.125.19.203, repr=<types.ImplicitFunc object at 0x7f784287dfa0>)
  File "/home1/pprabhu/.local/lib/python3.8/site-packages/ray/tune/function_runner.py", line 260, in run
    self._entrypoint()
  File "/home1/pprabhu/.local/lib/python3.8/site-packages/ray/tune/function_runner.py", line 328, in entrypoint
    return self._trainable_func(self.config, self._status_reporter,
  File "/home1/pprabhu/.local/lib/python3.8/site-packages/ray/tune/function_runner.py", line 594, in _trainable_func
    output = fn()
  File "/project/tbrun_769/qdec/source/neural_net.py", line 47, in train
    train_syndromes, train_error_labels, valid_syndromes, valid_error_labels = args
ValueError: too many values to unpack (expected 4)
2021-10-17 21:48:56,383	ERROR trial_runner.py:846 -- Trial DEFAULT_ab22e_00007: Error processing event.
Traceback (most recent call last):
  File "/home1/pprabhu/.local/lib/python3.8/site-packages/ray/tune/trial_runner.py", line 812, in _process_trial
    results = self.trial_executor.fetch_result(trial)
  File "/home1/pprabhu/.local/lib/python3.8/site-packages/ray/tune/ray_trial_executor.py", line 767, in fetch_result
    result = ray.get(trial_future[0], timeout=DEFAULT_GET_TIMEOUT)
  File "/home1/pprabhu/.local/lib/python3.8/site-packages/ray/_private/client_mode_hook.py", line 89, in wrapper
    return func(*args, **kwargs)
  File "/home1/pprabhu/.local/lib/python3.8/site-packages/ray/worker.py", line 1621, in get
    raise value.as_instanceof_cause()
ray.exceptions.RayTaskError(TuneError): [36mray::ImplicitFunc.train_buffered()[39m (pid=22064, ip=10.125.19.203, repr=<types.ImplicitFunc object at 0x7f266c798fd0>)
  File "/home1/pprabhu/.local/lib/python3.8/site-packages/ray/tune/trainable.py", line 189, in train_buffered
    result = self.train()
  File "/home1/pprabhu/.local/lib/python3.8/site-packages/ray/tune/trainable.py", line 248, in train
    result = self.step()
  File "/home1/pprabhu/.local/lib/python3.8/site-packages/ray/tune/function_runner.py", line 379, in step
    self._report_thread_runner_error(block=True)
  File "/home1/pprabhu/.local/lib/python3.8/site-packages/ray/tune/function_runner.py", line 526, in _report_thread_runner_error
    raise TuneError(
ray.tune.error.TuneError: Trial raised an exception. Traceback:
[36mray::ImplicitFunc.train_buffered()[39m (pid=22064, ip=10.125.19.203, repr=<types.ImplicitFunc object at 0x7f266c798fd0>)
  File "/home1/pprabhu/.local/lib/python3.8/site-packages/ray/tune/function_runner.py", line 260, in run
    self._entrypoint()
  File "/home1/pprabhu/.local/lib/python3.8/site-packages/ray/tune/function_runner.py", line 328, in entrypoint
    return self._trainable_func(self.config, self._status_reporter,
  File "/home1/pprabhu/.local/lib/python3.8/site-packages/ray/tune/function_runner.py", line 594, in _trainable_func
    output = fn()
  File "/project/tbrun_769/qdec/source/neural_net.py", line 47, in train
    train_syndromes, train_error_labels, valid_syndromes, valid_error_labels = args
ValueError: too many values to unpack (expected 4)
10_17_21_48_34_374 [22, 50, 50, 60, 60, 46] [Tanh(), Tanh(), Tanh(), Tanh(), Sigmoid()] 100 0.001 35
== Status ==
Memory usage on this node: 11.4/188.6 GiB
Using AsyncHyperBand: num_stopped=0
Bracket: Iter 32.000: None | Iter 16.000: None | Iter 8.000: None | Iter 4.000: None | Iter 2.000: None | Iter 1.000: None
Resources requested: 2.0/24 CPUs, 0/0 GPUs, 0.0/117.9 GiB heap, 0.0/54.52 GiB objects
Result logdir: /home1/pprabhu/ray_results/DEFAULT_2021-10-17_21-48-42
Number of trials: 8/8 (7 PENDING, 1 RUNNING)
+---------------------+----------+-------+----------+
| Trial name          | status   | loc   |   trials |
|---------------------+----------+-------+----------|
| DEFAULT_ab22e_00000 | RUNNING  |       |       50 |
| DEFAULT_ab22e_00001 | PENDING  |       |       25 |
| DEFAULT_ab22e_00002 | PENDING  |       |       15 |
| DEFAULT_ab22e_00003 | PENDING  |       |       30 |
| DEFAULT_ab22e_00004 | PENDING  |       |       70 |
| DEFAULT_ab22e_00005 | PENDING  |       |       70 |
| DEFAULT_ab22e_00006 | PENDING  |       |       20 |
| DEFAULT_ab22e_00007 | PENDING  |       |       20 |
+---------------------+----------+-------+----------+


== Status ==
Memory usage on this node: 12.7/188.6 GiB
Using AsyncHyperBand: num_stopped=0
Bracket: Iter 32.000: None | Iter 16.000: None | Iter 8.000: None | Iter 4.000: None | Iter 2.000: None | Iter 1.000: None
Resources requested: 16.0/24 CPUs, 0/0 GPUs, 0.0/117.9 GiB heap, 0.0/54.52 GiB objects
Result logdir: /home1/pprabhu/ray_results/DEFAULT_2021-10-17_21-48-42
Number of trials: 8/8 (8 RUNNING)
+---------------------+----------+-------+----------+
| Trial name          | status   | loc   |   trials |
|---------------------+----------+-------+----------|
| DEFAULT_ab22e_00000 | RUNNING  |       |       50 |
| DEFAULT_ab22e_00001 | RUNNING  |       |       25 |
| DEFAULT_ab22e_00002 | RUNNING  |       |       15 |
| DEFAULT_ab22e_00003 | RUNNING  |       |       30 |
| DEFAULT_ab22e_00004 | RUNNING  |       |       70 |
| DEFAULT_ab22e_00005 | RUNNING  |       |       70 |
| DEFAULT_ab22e_00006 | RUNNING  |       |       20 |
| DEFAULT_ab22e_00007 | RUNNING  |       |       20 |
+---------------------+----------+-------+----------+


Result for DEFAULT_ab22e_00000:
  {}
  
Result for DEFAULT_ab22e_00001:
  {}
  
Result for DEFAULT_ab22e_00002:
  {}
  
Result for DEFAULT_ab22e_00003:
  {}
  
Result for DEFAULT_ab22e_00005:
  {}
  
== Status ==
Memory usage on this node: 12.4/188.6 GiB
Using AsyncHyperBand: num_stopped=0
Bracket: Iter 32.000: None | Iter 16.000: None | Iter 8.000: None | Iter 4.000: None | Iter 2.000: None | Iter 1.000: None
Resources requested: 6.0/24 CPUs, 0/0 GPUs, 0.0/117.9 GiB heap, 0.0/54.52 GiB objects
Result logdir: /home1/pprabhu/ray_results/DEFAULT_2021-10-17_21-48-42
Number of trials: 8/8 (5 ERROR, 3 RUNNING)
+---------------------+----------+-------+----------+
| Trial name          | status   | loc   |   trials |
|---------------------+----------+-------+----------|
| DEFAULT_ab22e_00004 | RUNNING  |       |       70 |
| DEFAULT_ab22e_00006 | RUNNING  |       |       20 |
| DEFAULT_ab22e_00007 | RUNNING  |       |       20 |
| DEFAULT_ab22e_00000 | ERROR    |       |       50 |
| DEFAULT_ab22e_00001 | ERROR    |       |       25 |
| DEFAULT_ab22e_00002 | ERROR    |       |       15 |
| DEFAULT_ab22e_00003 | ERROR    |       |       30 |
| DEFAULT_ab22e_00005 | ERROR    |       |       70 |
+---------------------+----------+-------+----------+
Number of errored trials: 5
+---------------------+--------------+------------------------------------------------------------------------------------------------------------------------+
| Trial name          |   # failures | error file                                                                                                             |
|---------------------+--------------+------------------------------------------------------------------------------------------------------------------------|
| DEFAULT_ab22e_00000 |            1 | /home1/pprabhu/ray_results/DEFAULT_2021-10-17_21-48-42/DEFAULT_ab22e_00000_0_trials=50.0_2021-10-17_21-48-44/error.txt |
| DEFAULT_ab22e_00001 |            1 | /home1/pprabhu/ray_results/DEFAULT_2021-10-17_21-48-42/DEFAULT_ab22e_00001_1_trials=25.0_2021-10-17_21-48-44/error.txt |
| DEFAULT_ab22e_00002 |            1 | /home1/pprabhu/ray_results/DEFAULT_2021-10-17_21-48-42/DEFAULT_ab22e_00002_2_trials=15.0_2021-10-17_21-48-44/error.txt |
| DEFAULT_ab22e_00003 |            1 | /home1/pprabhu/ray_results/DEFAULT_2021-10-17_21-48-42/DEFAULT_ab22e_00003_3_trials=30.0_2021-10-17_21-48-45/error.txt |
| DEFAULT_ab22e_00005 |            1 | /home1/pprabhu/ray_results/DEFAULT_2021-10-17_21-48-42/DEFAULT_ab22e_00005_5_trials=70.0_2021-10-17_21-48-46/error.txt |
+---------------------+--------------+------------------------------------------------------------------------------------------------------------------------+

Result for DEFAULT_ab22e_00004:
  {}
  
Result for DEFAULT_ab22e_00006:
  {}
  
Result for DEFAULT_ab22e_00007:
  {}
  
== Status ==
Memory usage on this node: 11.6/188.6 GiB
Using AsyncHyperBand: num_stopped=0
Bracket: Iter 32.000: None | Iter 16.000: None | Iter 8.000: None | Iter 4.000: None | Iter 2.000: None | Iter 1.000: None
Resources requested: 0/24 CPUs, 0/0 GPUs, 0.0/117.9 GiB heap, 0.0/54.52 GiB objects
Result logdir: /home1/pprabhu/ray_results/DEFAULT_2021-10-17_21-48-42
Number of trials: 8/8 (8 ERROR)
+---------------------+----------+-------+----------+
| Trial name          | status   | loc   |   trials |
|---------------------+----------+-------+----------|
| DEFAULT_ab22e_00000 | ERROR    |       |       50 |
| DEFAULT_ab22e_00001 | ERROR    |       |       25 |
| DEFAULT_ab22e_00002 | ERROR    |       |       15 |
| DEFAULT_ab22e_00003 | ERROR    |       |       30 |
| DEFAULT_ab22e_00004 | ERROR    |       |       70 |
| DEFAULT_ab22e_00005 | ERROR    |       |       70 |
| DEFAULT_ab22e_00006 | ERROR    |       |       20 |
| DEFAULT_ab22e_00007 | ERROR    |       |       20 |
+---------------------+----------+-------+----------+
Number of errored trials: 8
+---------------------+--------------+------------------------------------------------------------------------------------------------------------------------+
| Trial name          |   # failures | error file                                                                                                             |
|---------------------+--------------+------------------------------------------------------------------------------------------------------------------------|
| DEFAULT_ab22e_00000 |            1 | /home1/pprabhu/ray_results/DEFAULT_2021-10-17_21-48-42/DEFAULT_ab22e_00000_0_trials=50.0_2021-10-17_21-48-44/error.txt |
| DEFAULT_ab22e_00001 |            1 | /home1/pprabhu/ray_results/DEFAULT_2021-10-17_21-48-42/DEFAULT_ab22e_00001_1_trials=25.0_2021-10-17_21-48-44/error.txt |
| DEFAULT_ab22e_00002 |            1 | /home1/pprabhu/ray_results/DEFAULT_2021-10-17_21-48-42/DEFAULT_ab22e_00002_2_trials=15.0_2021-10-17_21-48-44/error.txt |
| DEFAULT_ab22e_00003 |            1 | /home1/pprabhu/ray_results/DEFAULT_2021-10-17_21-48-42/DEFAULT_ab22e_00003_3_trials=30.0_2021-10-17_21-48-45/error.txt |
| DEFAULT_ab22e_00004 |            1 | /home1/pprabhu/ray_results/DEFAULT_2021-10-17_21-48-42/DEFAULT_ab22e_00004_4_trials=70.0_2021-10-17_21-48-45/error.txt |
| DEFAULT_ab22e_00005 |            1 | /home1/pprabhu/ray_results/DEFAULT_2021-10-17_21-48-42/DEFAULT_ab22e_00005_5_trials=70.0_2021-10-17_21-48-46/error.txt |
| DEFAULT_ab22e_00006 |            1 | /home1/pprabhu/ray_results/DEFAULT_2021-10-17_21-48-42/DEFAULT_ab22e_00006_6_trials=20.0_2021-10-17_21-48-47/error.txt |
| DEFAULT_ab22e_00007 |            1 | /home1/pprabhu/ray_results/DEFAULT_2021-10-17_21-48-42/DEFAULT_ab22e_00007_7_trials=20.0_2021-10-17_21-48-48/error.txt |
+---------------------+--------------+------------------------------------------------------------------------------------------------------------------------+

Traceback (most recent call last):
  File "source/pprabhu_driver.py", line 128, in <module>
    result = tune.run(
  File "/home1/pprabhu/.local/lib/python3.8/site-packages/ray/tune/tune.py", line 611, in run
    raise TuneError("Trials did not complete", incomplete_trials)
ray.tune.error.TuneError: ('Trials did not complete', [DEFAULT_ab22e_00000, DEFAULT_ab22e_00001, DEFAULT_ab22e_00002, DEFAULT_ab22e_00003, DEFAULT_ab22e_00004, DEFAULT_ab22e_00005, DEFAULT_ab22e_00006, DEFAULT_ab22e_00007])
