==========================================
SLURM_JOB_ID = 6215305
SLURM_JOB_NODELIST = d05-29
TMPDIR = /tmp/SLURM_6215305
==========================================
2021-10-17 22:35:27,705	WARNING experiment.py:302 -- No name detected on trainable. Using DEFAULT.
2021-10-17 22:35:27,706	INFO registry.py:66 -- Detected unknown callable for trainable. Converting to class.
[2m[36m(pid=26950)[0m 2021-10-17 22:35:35,699	ERROR function_runner.py:266 -- Runner Thread raised error.
[2m[36m(pid=26950)[0m Traceback (most recent call last):
[2m[36m(pid=26950)[0m   File "/home1/pprabhu/.local/lib/python3.8/site-packages/ray/tune/function_runner.py", line 260, in run
[2m[36m(pid=26950)[0m     self._entrypoint()
[2m[36m(pid=26950)[0m   File "/home1/pprabhu/.local/lib/python3.8/site-packages/ray/tune/function_runner.py", line 328, in entrypoint
[2m[36m(pid=26950)[0m     return self._trainable_func(self.config, self._status_reporter,
[2m[36m(pid=26950)[0m   File "/home1/pprabhu/.local/lib/python3.8/site-packages/ray/util/tracing/tracing_helper.py", line 449, in _resume_span
[2m[36m(pid=26950)[0m     return method(self, *_args, **_kwargs)
[2m[36m(pid=26950)[0m   File "/home1/pprabhu/.local/lib/python3.8/site-packages/ray/tune/function_runner.py", line 594, in _trainable_func
[2m[36m(pid=26950)[0m     output = fn()
[2m[36m(pid=26950)[0m   File "/project/tbrun_769/qdec/source/neural_net.py", line 52, in train
[2m[36m(pid=26950)[0m     data = dl.dataloader(dataset,device)
[2m[36m(pid=26950)[0m NameError: name 'dataset' is not defined
[2m[36m(pid=26950)[0m Exception in thread Thread-2:
[2m[36m(pid=26950)[0m Traceback (most recent call last):
[2m[36m(pid=26950)[0m   File "/project/tbrun_769/envs/qdec/lib/python3.8/threading.py", line 932, in _bootstrap_inner
[2m[36m(pid=26950)[0m     self.run()
[2m[36m(pid=26950)[0m   File "/home1/pprabhu/.local/lib/python3.8/site-packages/ray/tune/function_runner.py", line 279, in run
[2m[36m(pid=26950)[0m     raise e
[2m[36m(pid=26950)[0m   File "/home1/pprabhu/.local/lib/python3.8/site-packages/ray/tune/function_runner.py", line 260, in run
[2m[36m(pid=26950)[0m     self._entrypoint()
[2m[36m(pid=26950)[0m   File "/home1/pprabhu/.local/lib/python3.8/site-packages/ray/tune/function_runner.py", line 328, in entrypoint
[2m[36m(pid=26950)[0m     return self._trainable_func(self.config, self._status_reporter,
[2m[36m(pid=26950)[0m   File "/home1/pprabhu/.local/lib/python3.8/site-packages/ray/util/tracing/tracing_helper.py", line 449, in _resume_span
[2m[36m(pid=26950)[0m     return method(self, *_args, **_kwargs)
[2m[36m(pid=26950)[0m   File "/home1/pprabhu/.local/lib/python3.8/site-packages/ray/tune/function_runner.py", line 594, in _trainable_func
[2m[36m(pid=26950)[0m     output = fn()
[2m[36m(pid=26950)[0m   File "/project/tbrun_769/qdec/source/neural_net.py", line 52, in train
[2m[36m(pid=26950)[0m     data = dl.dataloader(dataset,device)
[2m[36m(pid=26950)[0m NameError: name 'dataset' is not defined
[2m[36m(pid=26953)[0m 2021-10-17 22:35:35,733	ERROR function_runner.py:266 -- Runner Thread raised error.
[2m[36m(pid=26953)[0m Traceback (most recent call last):
[2m[36m(pid=26953)[0m   File "/home1/pprabhu/.local/lib/python3.8/site-packages/ray/tune/function_runner.py", line 260, in run
[2m[36m(pid=26953)[0m     self._entrypoint()
[2m[36m(pid=26953)[0m   File "/home1/pprabhu/.local/lib/python3.8/site-packages/ray/tune/function_runner.py", line 328, in entrypoint
[2m[36m(pid=26953)[0m     return self._trainable_func(self.config, self._status_reporter,
[2m[36m(pid=26953)[0m   File "/home1/pprabhu/.local/lib/python3.8/site-packages/ray/util/tracing/tracing_helper.py", line 449, in _resume_span
[2m[36m(pid=26953)[0m     return method(self, *_args, **_kwargs)
[2m[36m(pid=26953)[0m   File "/home1/pprabhu/.local/lib/python3.8/site-packages/ray/tune/function_runner.py", line 594, in _trainable_func
[2m[36m(pid=26953)[0m     output = fn()
[2m[36m(pid=26953)[0m   File "/project/tbrun_769/qdec/source/neural_net.py", line 52, in train
[2m[36m(pid=26953)[0m     data = dl.dataloader(dataset,device)
[2m[36m(pid=26953)[0m NameError: name 'dataset' is not defined
[2m[36m(pid=26953)[0m Exception in thread Thread-2:
[2m[36m(pid=26953)[0m Traceback (most recent call last):
[2m[36m(pid=26953)[0m   File "/project/tbrun_769/envs/qdec/lib/python3.8/threading.py", line 932, in _bootstrap_inner
[2m[36m(pid=26953)[0m     self.run()
[2m[36m(pid=26953)[0m   File "/home1/pprabhu/.local/lib/python3.8/site-packages/ray/tune/function_runner.py", line 279, in run
[2m[36m(pid=26953)[0m     raise e
[2m[36m(pid=26953)[0m   File "/home1/pprabhu/.local/lib/python3.8/site-packages/ray/tune/function_runner.py", line 260, in run
[2m[36m(pid=26953)[0m     self._entrypoint()
[2m[36m(pid=26953)[0m   File "/home1/pprabhu/.local/lib/python3.8/site-packages/ray/tune/function_runner.py", line 328, in entrypoint
[2m[36m(pid=26953)[0m     return self._trainable_func(self.config, self._status_reporter,
[2m[36m(pid=26953)[0m   File "/home1/pprabhu/.local/lib/python3.8/site-packages/ray/util/tracing/tracing_helper.py", line 449, in _resume_span
[2m[36m(pid=26953)[0m     return method(self, *_args, **_kwargs)
[2m[36m(pid=26953)[0m   File "/home1/pprabhu/.local/lib/python3.8/site-packages/ray/tune/function_runner.py", line 594, in _trainable_func
[2m[36m(pid=26953)[0m     output = fn()
[2m[36m(pid=26953)[0m   File "/project/tbrun_769/qdec/source/neural_net.py", line 52, in train
[2m[36m(pid=26953)[0m     data = dl.dataloader(dataset,device)
[2m[36m(pid=26953)[0m NameError: name 'dataset' is not defined
[2m[36m(pid=26951)[0m 2021-10-17 22:35:35,769	ERROR function_runner.py:266 -- Runner Thread raised error.
[2m[36m(pid=26951)[0m Traceback (most recent call last):
[2m[36m(pid=26951)[0m   File "/home1/pprabhu/.local/lib/python3.8/site-packages/ray/tune/function_runner.py", line 260, in run
[2m[36m(pid=26951)[0m     self._entrypoint()
[2m[36m(pid=26951)[0m   File "/home1/pprabhu/.local/lib/python3.8/site-packages/ray/tune/function_runner.py", line 328, in entrypoint
[2m[36m(pid=26951)[0m     return self._trainable_func(self.config, self._status_reporter,
[2m[36m(pid=26951)[0m   File "/home1/pprabhu/.local/lib/python3.8/site-packages/ray/util/tracing/tracing_helper.py", line 449, in _resume_span
[2m[36m(pid=26951)[0m     return method(self, *_args, **_kwargs)
[2m[36m(pid=26951)[0m   File "/home1/pprabhu/.local/lib/python3.8/site-packages/ray/tune/function_runner.py", line 594, in _trainable_func
[2m[36m(pid=26951)[0m     output = fn()
[2m[36m(pid=26951)[0m   File "/project/tbrun_769/qdec/source/neural_net.py", line 52, in train
[2m[36m(pid=26951)[0m     data = dl.dataloader(dataset,device)
[2m[36m(pid=26951)[0m NameError: name 'dataset' is not defined
[2m[36m(pid=26951)[0m Exception in thread Thread-2:
[2m[36m(pid=26951)[0m Traceback (most recent call last):
[2m[36m(pid=26951)[0m   File "/project/tbrun_769/envs/qdec/lib/python3.8/threading.py", line 932, in _bootstrap_inner
[2m[36m(pid=26951)[0m     self.run()
[2m[36m(pid=26951)[0m   File "/home1/pprabhu/.local/lib/python3.8/site-packages/ray/tune/function_runner.py", line 279, in run
[2m[36m(pid=26951)[0m     raise e
[2m[36m(pid=26951)[0m   File "/home1/pprabhu/.local/lib/python3.8/site-packages/ray/tune/function_runner.py", line 260, in run
[2m[36m(pid=26951)[0m     self._entrypoint()
[2m[36m(pid=26951)[0m   File "/home1/pprabhu/.local/lib/python3.8/site-packages/ray/tune/function_runner.py", line 328, in entrypoint
[2m[36m(pid=26951)[0m     return self._trainable_func(self.config, self._status_reporter,
[2m[36m(pid=26951)[0m   File "/home1/pprabhu/.local/lib/python3.8/site-packages/ray/util/tracing/tracing_helper.py", line 449, in _resume_span
[2m[36m(pid=26951)[0m     return method(self, *_args, **_kwargs)
[2m[36m(pid=26951)[0m   File "/home1/pprabhu/.local/lib/python3.8/site-packages/ray/tune/function_runner.py", line 594, in _trainable_func
[2m[36m(pid=26951)[0m     output = fn()
[2m[36m(pid=26951)[0m   File "/project/tbrun_769/qdec/source/neural_net.py", line 52, in train
[2m[36m(pid=26951)[0m     data = dl.dataloader(dataset,device)
[2m[36m(pid=26951)[0m NameError: name 'dataset' is not defined
[2m[36m(pid=26954)[0m 2021-10-17 22:35:35,826	ERROR function_runner.py:266 -- Runner Thread raised error.
[2m[36m(pid=26954)[0m Traceback (most recent call last):
[2m[36m(pid=26954)[0m   File "/home1/pprabhu/.local/lib/python3.8/site-packages/ray/tune/function_runner.py", line 260, in run
[2m[36m(pid=26954)[0m     self._entrypoint()
[2m[36m(pid=26954)[0m   File "/home1/pprabhu/.local/lib/python3.8/site-packages/ray/tune/function_runner.py", line 328, in entrypoint
[2m[36m(pid=26954)[0m     return self._trainable_func(self.config, self._status_reporter,
[2m[36m(pid=26954)[0m   File "/home1/pprabhu/.local/lib/python3.8/site-packages/ray/util/tracing/tracing_helper.py", line 449, in _resume_span
[2m[36m(pid=26954)[0m     return method(self, *_args, **_kwargs)
[2m[36m(pid=26954)[0m   File "/home1/pprabhu/.local/lib/python3.8/site-packages/ray/tune/function_runner.py", line 594, in _trainable_func
[2m[36m(pid=26954)[0m     output = fn()
[2m[36m(pid=26954)[0m   File "/project/tbrun_769/qdec/source/neural_net.py", line 52, in train
[2m[36m(pid=26954)[0m     data = dl.dataloader(dataset,device)
[2m[36m(pid=26954)[0m NameError: name 'dataset' is not defined
[2m[36m(pid=26954)[0m Exception in thread Thread-2:
[2m[36m(pid=26954)[0m Traceback (most recent call last):
[2m[36m(pid=26954)[0m   File "/project/tbrun_769/envs/qdec/lib/python3.8/threading.py", line 932, in _bootstrap_inner
[2m[36m(pid=26954)[0m     self.run()
[2m[36m(pid=26954)[0m   File "/home1/pprabhu/.local/lib/python3.8/site-packages/ray/tune/function_runner.py", line 279, in run
[2m[36m(pid=26954)[0m     raise e
[2m[36m(pid=26954)[0m   File "/home1/pprabhu/.local/lib/python3.8/site-packages/ray/tune/function_runner.py", line 260, in run
[2m[36m(pid=26954)[0m     self._entrypoint()
[2m[36m(pid=26954)[0m   File "/home1/pprabhu/.local/lib/python3.8/site-packages/ray/tune/function_runner.py", line 328, in entrypoint
[2m[36m(pid=26954)[0m     return self._trainable_func(self.config, self._status_reporter,
[2m[36m(pid=26954)[0m   File "/home1/pprabhu/.local/lib/python3.8/site-packages/ray/util/tracing/tracing_helper.py", line 449, in _resume_span
[2m[36m(pid=26954)[0m     return method(self, *_args, **_kwargs)
[2m[36m(pid=26954)[0m   File "/home1/pprabhu/.local/lib/python3.8/site-packages/ray/tune/function_runner.py", line 594, in _trainable_func
[2m[36m(pid=26954)[0m     output = fn()
[2m[36m(pid=26954)[0m   File "/project/tbrun_769/qdec/source/neural_net.py", line 52, in train
[2m[36m(pid=26954)[0m     data = dl.dataloader(dataset,device)
[2m[36m(pid=26954)[0m NameError: name 'dataset' is not defined
[2m[36m(pid=26956)[0m 2021-10-17 22:35:35,793	ERROR function_runner.py:266 -- Runner Thread raised error.
[2m[36m(pid=26956)[0m Traceback (most recent call last):
[2m[36m(pid=26956)[0m   File "/home1/pprabhu/.local/lib/python3.8/site-packages/ray/tune/function_runner.py", line 260, in run
[2m[36m(pid=26956)[0m     self._entrypoint()
[2m[36m(pid=26956)[0m   File "/home1/pprabhu/.local/lib/python3.8/site-packages/ray/tune/function_runner.py", line 328, in entrypoint
[2m[36m(pid=26956)[0m     return self._trainable_func(self.config, self._status_reporter,
[2m[36m(pid=26956)[0m   File "/home1/pprabhu/.local/lib/python3.8/site-packages/ray/util/tracing/tracing_helper.py", line 449, in _resume_span
[2m[36m(pid=26956)[0m     return method(self, *_args, **_kwargs)
[2m[36m(pid=26956)[0m   File "/home1/pprabhu/.local/lib/python3.8/site-packages/ray/tune/function_runner.py", line 594, in _trainable_func
[2m[36m(pid=26956)[0m     output = fn()
[2m[36m(pid=26956)[0m   File "/project/tbrun_769/qdec/source/neural_net.py", line 52, in train
[2m[36m(pid=26956)[0m     data = dl.dataloader(dataset,device)
[2m[36m(pid=26956)[0m NameError: name 'dataset' is not defined
[2m[36m(pid=26956)[0m Exception in thread Thread-2:
[2m[36m(pid=26956)[0m Traceback (most recent call last):
[2m[36m(pid=26956)[0m   File "/project/tbrun_769/envs/qdec/lib/python3.8/threading.py", line 932, in _bootstrap_inner
[2m[36m(pid=26956)[0m     self.run()
[2m[36m(pid=26956)[0m   File "/home1/pprabhu/.local/lib/python3.8/site-packages/ray/tune/function_runner.py", line 279, in run
[2m[36m(pid=26956)[0m     raise e
[2m[36m(pid=26956)[0m   File "/home1/pprabhu/.local/lib/python3.8/site-packages/ray/tune/function_runner.py", line 260, in run
[2m[36m(pid=26956)[0m     self._entrypoint()
[2m[36m(pid=26956)[0m   File "/home1/pprabhu/.local/lib/python3.8/site-packages/ray/tune/function_runner.py", line 328, in entrypoint
[2m[36m(pid=26956)[0m     return self._trainable_func(self.config, self._status_reporter,
[2m[36m(pid=26956)[0m   File "/home1/pprabhu/.local/lib/python3.8/site-packages/ray/util/tracing/tracing_helper.py", line 449, in _resume_span
[2m[36m(pid=26956)[0m     return method(self, *_args, **_kwargs)
[2m[36m(pid=26956)[0m   File "/home1/pprabhu/.local/lib/python3.8/site-packages/ray/tune/function_runner.py", line 594, in _trainable_func
[2m[36m(pid=26956)[0m     output = fn()
[2m[36m(pid=26956)[0m   File "/project/tbrun_769/qdec/source/neural_net.py", line 52, in train
[2m[36m(pid=26956)[0m     data = dl.dataloader(dataset,device)
[2m[36m(pid=26956)[0m NameError: name 'dataset' is not defined
[2m[36m(pid=26949)[0m 2021-10-17 22:35:35,838	ERROR function_runner.py:266 -- Runner Thread raised error.
[2m[36m(pid=26949)[0m Traceback (most recent call last):
[2m[36m(pid=26949)[0m   File "/home1/pprabhu/.local/lib/python3.8/site-packages/ray/tune/function_runner.py", line 260, in run
[2m[36m(pid=26949)[0m     self._entrypoint()
[2m[36m(pid=26949)[0m   File "/home1/pprabhu/.local/lib/python3.8/site-packages/ray/tune/function_runner.py", line 328, in entrypoint
[2m[36m(pid=26949)[0m     return self._trainable_func(self.config, self._status_reporter,
[2m[36m(pid=26949)[0m   File "/home1/pprabhu/.local/lib/python3.8/site-packages/ray/util/tracing/tracing_helper.py", line 449, in _resume_span
[2m[36m(pid=26949)[0m     return method(self, *_args, **_kwargs)
[2m[36m(pid=26949)[0m   File "/home1/pprabhu/.local/lib/python3.8/site-packages/ray/tune/function_runner.py", line 594, in _trainable_func
[2m[36m(pid=26949)[0m     output = fn()
[2m[36m(pid=26949)[0m   File "/project/tbrun_769/qdec/source/neural_net.py", line 52, in train
[2m[36m(pid=26949)[0m     data = dl.dataloader(dataset,device)
[2m[36m(pid=26949)[0m NameError: name 'dataset' is not defined
[2m[36m(pid=26949)[0m Exception in thread Thread-2:
[2m[36m(pid=26949)[0m Traceback (most recent call last):
[2m[36m(pid=26949)[0m   File "/project/tbrun_769/envs/qdec/lib/python3.8/threading.py", line 932, in _bootstrap_inner
[2m[36m(pid=26949)[0m     self.run()
[2m[36m(pid=26949)[0m   File "/home1/pprabhu/.local/lib/python3.8/site-packages/ray/tune/function_runner.py", line 279, in run
[2m[36m(pid=26949)[0m     raise e
[2m[36m(pid=26949)[0m   File "/home1/pprabhu/.local/lib/python3.8/site-packages/ray/tune/function_runner.py", line 260, in run
[2m[36m(pid=26949)[0m     self._entrypoint()
[2m[36m(pid=26949)[0m   File "/home1/pprabhu/.local/lib/python3.8/site-packages/ray/tune/function_runner.py", line 328, in entrypoint
[2m[36m(pid=26949)[0m     return self._trainable_func(self.config, self._status_reporter,
[2m[36m(pid=26949)[0m   File "/home1/pprabhu/.local/lib/python3.8/site-packages/ray/util/tracing/tracing_helper.py", line 449, in _resume_span
[2m[36m(pid=26955)[0m 2021-10-17 22:35:35,818	ERROR function_runner.py:266 -- Runner Thread raised error.
[2m[36m(pid=26955)[0m Traceback (most recent call last):
[2m[36m(pid=26955)[0m   File "/home1/pprabhu/.local/lib/python3.8/site-packages/ray/tune/function_runner.py", line 260, in run
[2m[36m(pid=26955)[0m     self._entrypoint()
[2m[36m(pid=26955)[0m   File "/home1/pprabhu/.local/lib/python3.8/site-packages/ray/tune/function_runner.py", line 328, in entrypoint
[2m[36m(pid=26955)[0m     return self._trainable_func(self.config, self._status_reporter,
[2m[36m(pid=26955)[0m   File "/home1/pprabhu/.local/lib/python3.8/site-packages/ray/util/tracing/tracing_helper.py", line 449, in _resume_span
[2m[36m(pid=26955)[0m     return method(self, *_args, **_kwargs)
[2m[36m(pid=26955)[0m   File "/home1/pprabhu/.local/lib/python3.8/site-packages/ray/tune/function_runner.py", line 594, in _trainable_func
[2m[36m(pid=26955)[0m     output = fn()
[2m[36m(pid=26955)[0m   File "/project/tbrun_769/qdec/source/neural_net.py", line 52, in train
[2m[36m(pid=26955)[0m     data = dl.dataloader(dataset,device)
[2m[36m(pid=26955)[0m NameError: name 'dataset' is not defined
[2m[36m(pid=26955)[0m Exception in thread Thread-2:
[2m[36m(pid=26955)[0m Traceback (most recent call last):
[2m[36m(pid=26955)[0m   File "/project/tbrun_769/envs/qdec/lib/python3.8/threading.py", line 932, in _bootstrap_inner
[2m[36m(pid=26955)[0m     self.run()
[2m[36m(pid=26955)[0m   File "/home1/pprabhu/.local/lib/python3.8/site-packages/ray/tune/function_runner.py", line 279, in run
[2m[36m(pid=26955)[0m     raise e
[2m[36m(pid=26955)[0m   File "/home1/pprabhu/.local/lib/python3.8/site-packages/ray/tune/function_runner.py", line 260, in run
[2m[36m(pid=26955)[0m     self._entrypoint()
[2m[36m(pid=26955)[0m   File "/home1/pprabhu/.local/lib/python3.8/site-packages/ray/tune/function_runner.py", line 328, in entrypoint
[2m[36m(pid=26955)[0m     return self._trainable_func(self.config, self._status_reporter,
[2m[36m(pid=26955)[0m   File "/home1/pprabhu/.local/lib/python3.8/site-packages/ray/util/tracing/tracing_helper.py", line 449, in _resume_span
[2m[36m(pid=26955)[0m     return method(self, *_args, **_kwargs)
[2m[36m(pid=26955)[0m   File "/home1/pprabhu/.local/lib/python3.8/site-packages/ray/tune/function_runner.py", line 594, in _trainable_func
[2m[36m(pid=26955)[0m     output = fn()
[2m[36m(pid=26955)[0m   File "/project/tbrun_769/qdec/source/neural_net.py", line 52, in train
[2m[36m(pid=26955)[0m     data = dl.dataloader(dataset,device)
[2m[36m(pid=26955)[0m NameError: name 'dataset' is not defined
[2m[36m(pid=26949)[0m     return method(self, *_args, **_kwargs)
[2m[36m(pid=26949)[0m   File "/home1/pprabhu/.local/lib/python3.8/site-packages/ray/tune/function_runner.py", line 594, in _trainable_func
[2m[36m(pid=26949)[0m     output = fn()
[2m[36m(pid=26949)[0m   File "/project/tbrun_769/qdec/source/neural_net.py", line 52, in train
[2m[36m(pid=26949)[0m     data = dl.dataloader(dataset,device)
[2m[36m(pid=26949)[0m NameError: name 'dataset' is not defined
2021-10-17 22:35:35,885	ERROR trial_runner.py:846 -- Trial DEFAULT_3355e_00000: Error processing event.
Traceback (most recent call last):
  File "/home1/pprabhu/.local/lib/python3.8/site-packages/ray/tune/trial_runner.py", line 812, in _process_trial
    results = self.trial_executor.fetch_result(trial)
  File "/home1/pprabhu/.local/lib/python3.8/site-packages/ray/tune/ray_trial_executor.py", line 767, in fetch_result
    result = ray.get(trial_future[0], timeout=DEFAULT_GET_TIMEOUT)
  File "/home1/pprabhu/.local/lib/python3.8/site-packages/ray/_private/client_mode_hook.py", line 89, in wrapper
    return func(*args, **kwargs)
  File "/home1/pprabhu/.local/lib/python3.8/site-packages/ray/worker.py", line 1621, in get
    raise value.as_instanceof_cause()
ray.exceptions.RayTaskError(TuneError): [36mray::ImplicitFunc.train_buffered()[39m (pid=26950, ip=10.125.19.203, repr=<types.ImplicitFunc object at 0x7fd1873a7370>)
  File "/home1/pprabhu/.local/lib/python3.8/site-packages/ray/tune/trainable.py", line 189, in train_buffered
    result = self.train()
  File "/home1/pprabhu/.local/lib/python3.8/site-packages/ray/tune/trainable.py", line 248, in train
    result = self.step()
  File "/home1/pprabhu/.local/lib/python3.8/site-packages/ray/tune/function_runner.py", line 379, in step
    self._report_thread_runner_error(block=True)
  File "/home1/pprabhu/.local/lib/python3.8/site-packages/ray/tune/function_runner.py", line 526, in _report_thread_runner_error
    raise TuneError(
ray.tune.error.TuneError: Trial raised an exception. Traceback:
[36mray::ImplicitFunc.train_buffered()[39m (pid=26950, ip=10.125.19.203, repr=<types.ImplicitFunc object at 0x7fd1873a7370>)
  File "/home1/pprabhu/.local/lib/python3.8/site-packages/ray/tune/function_runner.py", line 260, in run
    self._entrypoint()
  File "/home1/pprabhu/.local/lib/python3.8/site-packages/ray/tune/function_runner.py", line 328, in entrypoint
    return self._trainable_func(self.config, self._status_reporter,
  File "/home1/pprabhu/.local/lib/python3.8/site-packages/ray/tune/function_runner.py", line 594, in _trainable_func
    output = fn()
  File "/project/tbrun_769/qdec/source/neural_net.py", line 52, in train
    data = dl.dataloader(dataset,device)
NameError: name 'dataset' is not defined
2021-10-17 22:35:35,923	ERROR trial_runner.py:846 -- Trial DEFAULT_3355e_00004: Error processing event.
Traceback (most recent call last):
  File "/home1/pprabhu/.local/lib/python3.8/site-packages/ray/tune/trial_runner.py", line 812, in _process_trial
    results = self.trial_executor.fetch_result(trial)
  File "/home1/pprabhu/.local/lib/python3.8/site-packages/ray/tune/ray_trial_executor.py", line 767, in fetch_result
    result = ray.get(trial_future[0], timeout=DEFAULT_GET_TIMEOUT)
  File "/home1/pprabhu/.local/lib/python3.8/site-packages/ray/_private/client_mode_hook.py", line 89, in wrapper
    return func(*args, **kwargs)
  File "/home1/pprabhu/.local/lib/python3.8/site-packages/ray/worker.py", line 1621, in get
    raise value.as_instanceof_cause()
ray.exceptions.RayTaskError(TuneError): [36mray::ImplicitFunc.train_buffered()[39m (pid=26953, ip=10.125.19.203, repr=<types.ImplicitFunc object at 0x7fe644a6d1c0>)
  File "/home1/pprabhu/.local/lib/python3.8/site-packages/ray/tune/trainable.py", line 189, in train_buffered
    result = self.train()
  File "/home1/pprabhu/.local/lib/python3.8/site-packages/ray/tune/trainable.py", line 248, in train
    result = self.step()
  File "/home1/pprabhu/.local/lib/python3.8/site-packages/ray/tune/function_runner.py", line 379, in step
    self._report_thread_runner_error(block=True)
  File "/home1/pprabhu/.local/lib/python3.8/site-packages/ray/tune/function_runner.py", line 526, in _report_thread_runner_error
    raise TuneError(
ray.tune.error.TuneError: Trial raised an exception. Traceback:
[36mray::ImplicitFunc.train_buffered()[39m (pid=26953, ip=10.125.19.203, repr=<types.ImplicitFunc object at 0x7fe644a6d1c0>)
  File "/home1/pprabhu/.local/lib/python3.8/site-packages/ray/tune/function_runner.py", line 260, in run
    self._entrypoint()
  File "/home1/pprabhu/.local/lib/python3.8/site-packages/ray/tune/function_runner.py", line 328, in entrypoint
    return self._trainable_func(self.config, self._status_reporter,
  File "/home1/pprabhu/.local/lib/python3.8/site-packages/ray/tune/function_runner.py", line 594, in _trainable_func
    output = fn()
  File "/project/tbrun_769/qdec/source/neural_net.py", line 52, in train
    data = dl.dataloader(dataset,device)
NameError: name 'dataset' is not defined
[2m[36m(pid=26948)[0m 2021-10-17 22:35:35,847	ERROR function_runner.py:266 -- Runner Thread raised error.
[2m[36m(pid=26948)[0m Traceback (most recent call last):
[2m[36m(pid=26948)[0m   File "/home1/pprabhu/.local/lib/python3.8/site-packages/ray/tune/function_runner.py", line 260, in run
[2m[36m(pid=26948)[0m     self._entrypoint()
[2m[36m(pid=26948)[0m   File "/home1/pprabhu/.local/lib/python3.8/site-packages/ray/tune/function_runner.py", line 328, in entrypoint
[2m[36m(pid=26948)[0m     return self._trainable_func(self.config, self._status_reporter,
[2m[36m(pid=26948)[0m   File "/home1/pprabhu/.local/lib/python3.8/site-packages/ray/util/tracing/tracing_helper.py", line 449, in _resume_span
[2m[36m(pid=26948)[0m     return method(self, *_args, **_kwargs)
[2m[36m(pid=26948)[0m   File "/home1/pprabhu/.local/lib/python3.8/site-packages/ray/tune/function_runner.py", line 594, in _trainable_func
[2m[36m(pid=26948)[0m     output = fn()
[2m[36m(pid=26948)[0m   File "/project/tbrun_769/qdec/source/neural_net.py", line 52, in train
[2m[36m(pid=26948)[0m     data = dl.dataloader(dataset,device)
[2m[36m(pid=26948)[0m NameError: name 'dataset' is not defined
[2m[36m(pid=26948)[0m Exception in thread Thread-2:
[2m[36m(pid=26948)[0m Traceback (most recent call last):
[2m[36m(pid=26948)[0m   File "/project/tbrun_769/envs/qdec/lib/python3.8/threading.py", line 932, in _bootstrap_inner
[2m[36m(pid=26948)[0m     self.run()
[2m[36m(pid=26948)[0m   File "/home1/pprabhu/.local/lib/python3.8/site-packages/ray/tune/function_runner.py", line 279, in run
[2m[36m(pid=26948)[0m     raise e
[2m[36m(pid=26948)[0m   File "/home1/pprabhu/.local/lib/python3.8/site-packages/ray/tune/function_runner.py", line 260, in run
[2m[36m(pid=26948)[0m     self._entrypoint()
[2m[36m(pid=26948)[0m   File "/home1/pprabhu/.local/lib/python3.8/site-packages/ray/tune/function_runner.py", line 328, in entrypoint
[2m[36m(pid=26948)[0m     return self._trainable_func(self.config, self._status_reporter,
[2m[36m(pid=26948)[0m   File "/home1/pprabhu/.local/lib/python3.8/site-packages/ray/util/tracing/tracing_helper.py", line 449, in _resume_span
[2m[36m(pid=26948)[0m     return method(self, *_args, **_kwargs)
[2m[36m(pid=26948)[0m   File "/home1/pprabhu/.local/lib/python3.8/site-packages/ray/tune/function_runner.py", line 594, in _trainable_func
[2m[36m(pid=26948)[0m     output = fn()
[2m[36m(pid=26948)[0m   File "/project/tbrun_769/qdec/source/neural_net.py", line 52, in train
[2m[36m(pid=26948)[0m     data = dl.dataloader(dataset,device)
[2m[36m(pid=26948)[0m NameError: name 'dataset' is not defined
2021-10-17 22:35:35,968	ERROR trial_runner.py:846 -- Trial DEFAULT_3355e_00006: Error processing event.
Traceback (most recent call last):
  File "/home1/pprabhu/.local/lib/python3.8/site-packages/ray/tune/trial_runner.py", line 812, in _process_trial
    results = self.trial_executor.fetch_result(trial)
  File "/home1/pprabhu/.local/lib/python3.8/site-packages/ray/tune/ray_trial_executor.py", line 767, in fetch_result
    result = ray.get(trial_future[0], timeout=DEFAULT_GET_TIMEOUT)
  File "/home1/pprabhu/.local/lib/python3.8/site-packages/ray/_private/client_mode_hook.py", line 89, in wrapper
    return func(*args, **kwargs)
  File "/home1/pprabhu/.local/lib/python3.8/site-packages/ray/worker.py", line 1621, in get
    raise value.as_instanceof_cause()
ray.exceptions.RayTaskError(TuneError): [36mray::ImplicitFunc.train_buffered()[39m (pid=26951, ip=10.125.19.203, repr=<types.ImplicitFunc object at 0x7f45ac4da1c0>)
  File "/home1/pprabhu/.local/lib/python3.8/site-packages/ray/tune/trainable.py", line 189, in train_buffered
    result = self.train()
  File "/home1/pprabhu/.local/lib/python3.8/site-packages/ray/tune/trainable.py", line 248, in train
    result = self.step()
  File "/home1/pprabhu/.local/lib/python3.8/site-packages/ray/tune/function_runner.py", line 379, in step
    self._report_thread_runner_error(block=True)
  File "/home1/pprabhu/.local/lib/python3.8/site-packages/ray/tune/function_runner.py", line 526, in _report_thread_runner_error
    raise TuneError(
ray.tune.error.TuneError: Trial raised an exception. Traceback:
[36mray::ImplicitFunc.train_buffered()[39m (pid=26951, ip=10.125.19.203, repr=<types.ImplicitFunc object at 0x7f45ac4da1c0>)
  File "/home1/pprabhu/.local/lib/python3.8/site-packages/ray/tune/function_runner.py", line 260, in run
    self._entrypoint()
  File "/home1/pprabhu/.local/lib/python3.8/site-packages/ray/tune/function_runner.py", line 328, in entrypoint
    return self._trainable_func(self.config, self._status_reporter,
  File "/home1/pprabhu/.local/lib/python3.8/site-packages/ray/tune/function_runner.py", line 594, in _trainable_func
    output = fn()
  File "/project/tbrun_769/qdec/source/neural_net.py", line 52, in train
    data = dl.dataloader(dataset,device)
NameError: name 'dataset' is not defined
2021-10-17 22:35:35,994	ERROR trial_runner.py:846 -- Trial DEFAULT_3355e_00001: Error processing event.
Traceback (most recent call last):
  File "/home1/pprabhu/.local/lib/python3.8/site-packages/ray/tune/trial_runner.py", line 812, in _process_trial
    results = self.trial_executor.fetch_result(trial)
  File "/home1/pprabhu/.local/lib/python3.8/site-packages/ray/tune/ray_trial_executor.py", line 767, in fetch_result
    result = ray.get(trial_future[0], timeout=DEFAULT_GET_TIMEOUT)
  File "/home1/pprabhu/.local/lib/python3.8/site-packages/ray/_private/client_mode_hook.py", line 89, in wrapper
    return func(*args, **kwargs)
  File "/home1/pprabhu/.local/lib/python3.8/site-packages/ray/worker.py", line 1621, in get
    raise value.as_instanceof_cause()
ray.exceptions.RayTaskError(TuneError): [36mray::ImplicitFunc.train_buffered()[39m (pid=26956, ip=10.125.19.203, repr=<types.ImplicitFunc object at 0x7f593a47d4c0>)
  File "/home1/pprabhu/.local/lib/python3.8/site-packages/ray/tune/trainable.py", line 189, in train_buffered
    result = self.train()
  File "/home1/pprabhu/.local/lib/python3.8/site-packages/ray/tune/trainable.py", line 248, in train
    result = self.step()
  File "/home1/pprabhu/.local/lib/python3.8/site-packages/ray/tune/function_runner.py", line 379, in step
    self._report_thread_runner_error(block=True)
  File "/home1/pprabhu/.local/lib/python3.8/site-packages/ray/tune/function_runner.py", line 526, in _report_thread_runner_error
    raise TuneError(
ray.tune.error.TuneError: Trial raised an exception. Traceback:
[36mray::ImplicitFunc.train_buffered()[39m (pid=26956, ip=10.125.19.203, repr=<types.ImplicitFunc object at 0x7f593a47d4c0>)
  File "/home1/pprabhu/.local/lib/python3.8/site-packages/ray/tune/function_runner.py", line 260, in run
    self._entrypoint()
  File "/home1/pprabhu/.local/lib/python3.8/site-packages/ray/tune/function_runner.py", line 328, in entrypoint
    return self._trainable_func(self.config, self._status_reporter,
  File "/home1/pprabhu/.local/lib/python3.8/site-packages/ray/tune/function_runner.py", line 594, in _trainable_func
    output = fn()
  File "/project/tbrun_769/qdec/source/neural_net.py", line 52, in train
    data = dl.dataloader(dataset,device)
NameError: name 'dataset' is not defined
2021-10-17 22:35:36,022	ERROR trial_runner.py:846 -- Trial DEFAULT_3355e_00003: Error processing event.
Traceback (most recent call last):
  File "/home1/pprabhu/.local/lib/python3.8/site-packages/ray/tune/trial_runner.py", line 812, in _process_trial
    results = self.trial_executor.fetch_result(trial)
  File "/home1/pprabhu/.local/lib/python3.8/site-packages/ray/tune/ray_trial_executor.py", line 767, in fetch_result
    result = ray.get(trial_future[0], timeout=DEFAULT_GET_TIMEOUT)
  File "/home1/pprabhu/.local/lib/python3.8/site-packages/ray/_private/client_mode_hook.py", line 89, in wrapper
    return func(*args, **kwargs)
  File "/home1/pprabhu/.local/lib/python3.8/site-packages/ray/worker.py", line 1621, in get
    raise value.as_instanceof_cause()
ray.exceptions.RayTaskError(TuneError): [36mray::ImplicitFunc.train_buffered()[39m (pid=26955, ip=10.125.19.203, repr=<types.ImplicitFunc object at 0x7efc0a6be310>)
  File "/home1/pprabhu/.local/lib/python3.8/site-packages/ray/tune/trainable.py", line 189, in train_buffered
    result = self.train()
  File "/home1/pprabhu/.local/lib/python3.8/site-packages/ray/tune/trainable.py", line 248, in train
    result = self.step()
  File "/home1/pprabhu/.local/lib/python3.8/site-packages/ray/tune/function_runner.py", line 379, in step
    self._report_thread_runner_error(block=True)
  File "/home1/pprabhu/.local/lib/python3.8/site-packages/ray/tune/function_runner.py", line 526, in _report_thread_runner_error
    raise TuneError(
ray.tune.error.TuneError: Trial raised an exception. Traceback:
[36mray::ImplicitFunc.train_buffered()[39m (pid=26955, ip=10.125.19.203, repr=<types.ImplicitFunc object at 0x7efc0a6be310>)
  File "/home1/pprabhu/.local/lib/python3.8/site-packages/ray/tune/function_runner.py", line 260, in run
    self._entrypoint()
  File "/home1/pprabhu/.local/lib/python3.8/site-packages/ray/tune/function_runner.py", line 328, in entrypoint
    return self._trainable_func(self.config, self._status_reporter,
  File "/home1/pprabhu/.local/lib/python3.8/site-packages/ray/tune/function_runner.py", line 594, in _trainable_func
    output = fn()
  File "/project/tbrun_769/qdec/source/neural_net.py", line 52, in train
    data = dl.dataloader(dataset,device)
NameError: name 'dataset' is not defined
2021-10-17 22:35:36,033	ERROR trial_runner.py:846 -- Trial DEFAULT_3355e_00007: Error processing event.
Traceback (most recent call last):
  File "/home1/pprabhu/.local/lib/python3.8/site-packages/ray/tune/trial_runner.py", line 812, in _process_trial
    results = self.trial_executor.fetch_result(trial)
  File "/home1/pprabhu/.local/lib/python3.8/site-packages/ray/tune/ray_trial_executor.py", line 767, in fetch_result
    result = ray.get(trial_future[0], timeout=DEFAULT_GET_TIMEOUT)
  File "/home1/pprabhu/.local/lib/python3.8/site-packages/ray/_private/client_mode_hook.py", line 89, in wrapper
    return func(*args, **kwargs)
  File "/home1/pprabhu/.local/lib/python3.8/site-packages/ray/worker.py", line 1621, in get
    raise value.as_instanceof_cause()
ray.exceptions.RayTaskError(TuneError): [36mray::ImplicitFunc.train_buffered()[39m (pid=26954, ip=10.125.19.203, repr=<types.ImplicitFunc object at 0x7fd780a73310>)
  File "/home1/pprabhu/.local/lib/python3.8/site-packages/ray/tune/trainable.py", line 189, in train_buffered
    result = self.train()
  File "/home1/pprabhu/.local/lib/python3.8/site-packages/ray/tune/trainable.py", line 248, in train
    result = self.step()
  File "/home1/pprabhu/.local/lib/python3.8/site-packages/ray/tune/function_runner.py", line 379, in step
    self._report_thread_runner_error(block=True)
  File "/home1/pprabhu/.local/lib/python3.8/site-packages/ray/tune/function_runner.py", line 526, in _report_thread_runner_error
    raise TuneError(
ray.tune.error.TuneError: Trial raised an exception. Traceback:
[36mray::ImplicitFunc.train_buffered()[39m (pid=26954, ip=10.125.19.203, repr=<types.ImplicitFunc object at 0x7fd780a73310>)
  File "/home1/pprabhu/.local/lib/python3.8/site-packages/ray/tune/function_runner.py", line 260, in run
    self._entrypoint()
  File "/home1/pprabhu/.local/lib/python3.8/site-packages/ray/tune/function_runner.py", line 328, in entrypoint
    return self._trainable_func(self.config, self._status_reporter,
  File "/home1/pprabhu/.local/lib/python3.8/site-packages/ray/tune/function_runner.py", line 594, in _trainable_func
    output = fn()
  File "/project/tbrun_769/qdec/source/neural_net.py", line 52, in train
    data = dl.dataloader(dataset,device)
NameError: name 'dataset' is not defined
2021-10-17 22:35:36,039	ERROR trial_runner.py:846 -- Trial DEFAULT_3355e_00002: Error processing event.
Traceback (most recent call last):
  File "/home1/pprabhu/.local/lib/python3.8/site-packages/ray/tune/trial_runner.py", line 812, in _process_trial
    results = self.trial_executor.fetch_result(trial)
  File "/home1/pprabhu/.local/lib/python3.8/site-packages/ray/tune/ray_trial_executor.py", line 767, in fetch_result
    result = ray.get(trial_future[0], timeout=DEFAULT_GET_TIMEOUT)
  File "/home1/pprabhu/.local/lib/python3.8/site-packages/ray/_private/client_mode_hook.py", line 89, in wrapper
    return func(*args, **kwargs)
  File "/home1/pprabhu/.local/lib/python3.8/site-packages/ray/worker.py", line 1621, in get
    raise value.as_instanceof_cause()
ray.exceptions.RayTaskError(TuneError): [36mray::ImplicitFunc.train_buffered()[39m (pid=26949, ip=10.125.19.203, repr=<types.ImplicitFunc object at 0x7fafba93f1c0>)
  File "/home1/pprabhu/.local/lib/python3.8/site-packages/ray/tune/trainable.py", line 189, in train_buffered
    result = self.train()
  File "/home1/pprabhu/.local/lib/python3.8/site-packages/ray/tune/trainable.py", line 248, in train
    result = self.step()
  File "/home1/pprabhu/.local/lib/python3.8/site-packages/ray/tune/function_runner.py", line 379, in step
    self._report_thread_runner_error(block=True)
  File "/home1/pprabhu/.local/lib/python3.8/site-packages/ray/tune/function_runner.py", line 526, in _report_thread_runner_error
    raise TuneError(
ray.tune.error.TuneError: Trial raised an exception. Traceback:
[36mray::ImplicitFunc.train_buffered()[39m (pid=26949, ip=10.125.19.203, repr=<types.ImplicitFunc object at 0x7fafba93f1c0>)
  File "/home1/pprabhu/.local/lib/python3.8/site-packages/ray/tune/function_runner.py", line 260, in run
    self._entrypoint()
  File "/home1/pprabhu/.local/lib/python3.8/site-packages/ray/tune/function_runner.py", line 328, in entrypoint
    return self._trainable_func(self.config, self._status_reporter,
  File "/home1/pprabhu/.local/lib/python3.8/site-packages/ray/tune/function_runner.py", line 594, in _trainable_func
    output = fn()
  File "/project/tbrun_769/qdec/source/neural_net.py", line 52, in train
    data = dl.dataloader(dataset,device)
NameError: name 'dataset' is not defined
2021-10-17 22:35:36,079	ERROR trial_runner.py:846 -- Trial DEFAULT_3355e_00005: Error processing event.
Traceback (most recent call last):
  File "/home1/pprabhu/.local/lib/python3.8/site-packages/ray/tune/trial_runner.py", line 812, in _process_trial
    results = self.trial_executor.fetch_result(trial)
  File "/home1/pprabhu/.local/lib/python3.8/site-packages/ray/tune/ray_trial_executor.py", line 767, in fetch_result
    result = ray.get(trial_future[0], timeout=DEFAULT_GET_TIMEOUT)
  File "/home1/pprabhu/.local/lib/python3.8/site-packages/ray/_private/client_mode_hook.py", line 89, in wrapper
    return func(*args, **kwargs)
  File "/home1/pprabhu/.local/lib/python3.8/site-packages/ray/worker.py", line 1621, in get
    raise value.as_instanceof_cause()
ray.exceptions.RayTaskError(TuneError): [36mray::ImplicitFunc.train_buffered()[39m (pid=26948, ip=10.125.19.203, repr=<types.ImplicitFunc object at 0x7fb6e82231c0>)
  File "/home1/pprabhu/.local/lib/python3.8/site-packages/ray/tune/trainable.py", line 189, in train_buffered
    result = self.train()
  File "/home1/pprabhu/.local/lib/python3.8/site-packages/ray/tune/trainable.py", line 248, in train
    result = self.step()
  File "/home1/pprabhu/.local/lib/python3.8/site-packages/ray/tune/function_runner.py", line 379, in step
    self._report_thread_runner_error(block=True)
  File "/home1/pprabhu/.local/lib/python3.8/site-packages/ray/tune/function_runner.py", line 526, in _report_thread_runner_error
    raise TuneError(
ray.tune.error.TuneError: Trial raised an exception. Traceback:
[36mray::ImplicitFunc.train_buffered()[39m (pid=26948, ip=10.125.19.203, repr=<types.ImplicitFunc object at 0x7fb6e82231c0>)
  File "/home1/pprabhu/.local/lib/python3.8/site-packages/ray/tune/function_runner.py", line 260, in run
    self._entrypoint()
  File "/home1/pprabhu/.local/lib/python3.8/site-packages/ray/tune/function_runner.py", line 328, in entrypoint
    return self._trainable_func(self.config, self._status_reporter,
  File "/home1/pprabhu/.local/lib/python3.8/site-packages/ray/tune/function_runner.py", line 594, in _trainable_func
    output = fn()
  File "/project/tbrun_769/qdec/source/neural_net.py", line 52, in train
    data = dl.dataloader(dataset,device)
NameError: name 'dataset' is not defined
10_17_22_35_20_434 [22, 50, 50, 60, 60, 46] [Tanh(), Tanh(), Tanh(), Tanh(), Sigmoid()] 100 0.001 35
== Status ==
Memory usage on this node: 14.5/188.6 GiB
Using AsyncHyperBand: num_stopped=0
Bracket: Iter 32.000: None | Iter 16.000: None | Iter 8.000: None | Iter 4.000: None | Iter 2.000: None | Iter 1.000: None
Resources requested: 2.0/24 CPUs, 0/0 GPUs, 0.0/115.41 GiB heap, 0.0/53.45 GiB objects
Result logdir: /home1/pprabhu/ray_results/DEFAULT_2021-10-17_22-35-27
Number of trials: 8/8 (7 PENDING, 1 RUNNING)
+---------------------+----------+-------+----------+
| Trial name          | status   | loc   |   trials |
|---------------------+----------+-------+----------|
| DEFAULT_3355e_00000 | RUNNING  |       |       60 |
| DEFAULT_3355e_00001 | PENDING  |       |       35 |
| DEFAULT_3355e_00002 | PENDING  |       |       70 |
| DEFAULT_3355e_00003 | PENDING  |       |       70 |
| DEFAULT_3355e_00004 | PENDING  |       |       25 |
| DEFAULT_3355e_00005 | PENDING  |       |       35 |
| DEFAULT_3355e_00006 | PENDING  |       |       65 |
| DEFAULT_3355e_00007 | PENDING  |       |       65 |
+---------------------+----------+-------+----------+


== Status ==
Memory usage on this node: 16.3/188.6 GiB
Using AsyncHyperBand: num_stopped=0
Bracket: Iter 32.000: None | Iter 16.000: None | Iter 8.000: None | Iter 4.000: None | Iter 2.000: None | Iter 1.000: None
Resources requested: 16.0/24 CPUs, 0/0 GPUs, 0.0/115.41 GiB heap, 0.0/53.45 GiB objects
Result logdir: /home1/pprabhu/ray_results/DEFAULT_2021-10-17_22-35-27
Number of trials: 8/8 (8 RUNNING)
+---------------------+----------+-------+----------+
| Trial name          | status   | loc   |   trials |
|---------------------+----------+-------+----------|
| DEFAULT_3355e_00000 | RUNNING  |       |       60 |
| DEFAULT_3355e_00001 | RUNNING  |       |       35 |
| DEFAULT_3355e_00002 | RUNNING  |       |       70 |
| DEFAULT_3355e_00003 | RUNNING  |       |       70 |
| DEFAULT_3355e_00004 | RUNNING  |       |       25 |
| DEFAULT_3355e_00005 | RUNNING  |       |       35 |
| DEFAULT_3355e_00006 | RUNNING  |       |       65 |
| DEFAULT_3355e_00007 | RUNNING  |       |       65 |
+---------------------+----------+-------+----------+


Result for DEFAULT_3355e_00000:
  {}
  
Result for DEFAULT_3355e_00004:
  {}
  
Result for DEFAULT_3355e_00006:
  {}
  
Result for DEFAULT_3355e_00001:
  {}
  
Result for DEFAULT_3355e_00003:
  {}
  
Result for DEFAULT_3355e_00007:
  {}
  
Result for DEFAULT_3355e_00002:
  {}
  
Result for DEFAULT_3355e_00005:
  {}
  
== Status ==
Memory usage on this node: 14.6/188.6 GiB
Using AsyncHyperBand: num_stopped=0
Bracket: Iter 32.000: None | Iter 16.000: None | Iter 8.000: None | Iter 4.000: None | Iter 2.000: None | Iter 1.000: None
Resources requested: 0/24 CPUs, 0/0 GPUs, 0.0/115.41 GiB heap, 0.0/53.45 GiB objects
Result logdir: /home1/pprabhu/ray_results/DEFAULT_2021-10-17_22-35-27
Number of trials: 8/8 (8 ERROR)
+---------------------+----------+-------+----------+
| Trial name          | status   | loc   |   trials |
|---------------------+----------+-------+----------|
| DEFAULT_3355e_00000 | ERROR    |       |       60 |
| DEFAULT_3355e_00001 | ERROR    |       |       35 |
| DEFAULT_3355e_00002 | ERROR    |       |       70 |
| DEFAULT_3355e_00003 | ERROR    |       |       70 |
| DEFAULT_3355e_00004 | ERROR    |       |       25 |
| DEFAULT_3355e_00005 | ERROR    |       |       35 |
| DEFAULT_3355e_00006 | ERROR    |       |       65 |
| DEFAULT_3355e_00007 | ERROR    |       |       65 |
+---------------------+----------+-------+----------+
Number of errored trials: 8
+---------------------+--------------+------------------------------------------------------------------------------------------------------------------------+
| Trial name          |   # failures | error file                                                                                                             |
|---------------------+--------------+------------------------------------------------------------------------------------------------------------------------|
| DEFAULT_3355e_00000 |            1 | /home1/pprabhu/ray_results/DEFAULT_2021-10-17_22-35-27/DEFAULT_3355e_00000_0_trials=60.0_2021-10-17_22-35-27/error.txt |
| DEFAULT_3355e_00001 |            1 | /home1/pprabhu/ray_results/DEFAULT_2021-10-17_22-35-27/DEFAULT_3355e_00001_1_trials=35.0_2021-10-17_22-35-28/error.txt |
| DEFAULT_3355e_00002 |            1 | /home1/pprabhu/ray_results/DEFAULT_2021-10-17_22-35-27/DEFAULT_3355e_00002_2_trials=70.0_2021-10-17_22-35-28/error.txt |
| DEFAULT_3355e_00003 |            1 | /home1/pprabhu/ray_results/DEFAULT_2021-10-17_22-35-27/DEFAULT_3355e_00003_3_trials=70.0_2021-10-17_22-35-28/error.txt |
| DEFAULT_3355e_00004 |            1 | /home1/pprabhu/ray_results/DEFAULT_2021-10-17_22-35-27/DEFAULT_3355e_00004_4_trials=25.0_2021-10-17_22-35-28/error.txt |
| DEFAULT_3355e_00005 |            1 | /home1/pprabhu/ray_results/DEFAULT_2021-10-17_22-35-27/DEFAULT_3355e_00005_5_trials=35.0_2021-10-17_22-35-28/error.txt |
| DEFAULT_3355e_00006 |            1 | /home1/pprabhu/ray_results/DEFAULT_2021-10-17_22-35-27/DEFAULT_3355e_00006_6_trials=65.0_2021-10-17_22-35-28/error.txt |
| DEFAULT_3355e_00007 |            1 | /home1/pprabhu/ray_results/DEFAULT_2021-10-17_22-35-27/DEFAULT_3355e_00007_7_trials=65.0_2021-10-17_22-35-28/error.txt |
+---------------------+--------------+------------------------------------------------------------------------------------------------------------------------+

Traceback (most recent call last):
  File "source/pprabhu_driver.py", line 119, in <module>
    result = tune.run(
  File "/home1/pprabhu/.local/lib/python3.8/site-packages/ray/tune/tune.py", line 611, in run
    raise TuneError("Trials did not complete", incomplete_trials)
ray.tune.error.TuneError: ('Trials did not complete', [DEFAULT_3355e_00000, DEFAULT_3355e_00001, DEFAULT_3355e_00002, DEFAULT_3355e_00003, DEFAULT_3355e_00004, DEFAULT_3355e_00005, DEFAULT_3355e_00006, DEFAULT_3355e_00007])
